Workbook

Sheet DES – Plaintext Avalanche
A1: Original Plaintext | B1: Flipped PT Bit # | C1: Original Plaintext (Hex) | T1: Original Plaintext (4-bit) | AK1: Original Plaintext (Bits) | CX1: Modified Plaintext | CY1: Modified Plaintext (Hex) | DP1: Modified Plaintext (4-bit) | EG1: Modified Plaintext (Bits) | GT1: Original Ciphertext | GU1: Original Ciphertext (Hex) | HL1: Original CT (4-bit) | IC1: Original CT (Bits) | KP1: Modified Ciphertext | KQ1: Modified Ciphertext (Hex) | LH1: Modified CT (4-bit) | LY1: Modified CT (Bits) | OL1: XOR (Orig CT ⊕ Mod CT bits) | QY1: Hamming Distance
T2: N1 | U2: N2 | V2: N3 | W2: N4 | X2: N5 | Y2: N6 | Z2: N7 | AA2: N8 | AB2: N9 | AC2: N10 | AD2: N11 | AE2: N12 | AF2: N13 | AG2: N14 | AH2: N15 | AI2: N16 | AK2: b1 | AL2: b2 | AM2: b3 | AN2: b4 | AO2: b5 | AP2: b6 | AQ2: b7 | AR2: b8 | AS2: b9 | AT2: b10 | AU2: b11 | AV2: b12 | AW2: b13 | AX2: b14 | AY2: b15 | AZ2: b16 | BA2: b17 | BB2: b18 | BC2: b19 | BD2: b20 | BE2: b21 | BF2: b22 | BG2: b23 | BH2: b24 | BI2: b25 | BJ2: b26 | BK2: b27 | BL2: b28 | BM2: b29 | BN2: b30 | BO2: b31 | BP2: b32 | BQ2: b33 | BR2: b34 | BS2: b35 | BT2: b36 | BU2: b37 | BV2: b38 | BW2: b39 | BX2: b40 | BY2: b41 | BZ2: b42 | CA2: b43 | CB2: b44 | CC2: b45 | CD2: b46 | CE2: b47 | CF2: b48 | CG2: b49 | CH2: b50 | CI2: b51 | CJ2: b52 | CK2: b53 | CL2: b54 | CM2: b55 | CN2: b56 | CO2: b57 | CP2: b58 | CQ2: b59 | CR2: b60 | CS2: b61 | CT2: b62 | CU2: b63 | CV2: b64 | DP2: N1 | DQ2: N2 | DR2: N3 | DS2: N4 | DT2: N5 | DU2: N6 | DV2: N7 | DW2: N8 | DX2: N9 | DY2: N10 | DZ2: N11 | EA2: N12 | EB2: N13 | EC2: N14 | ED2: N15 | EE2: N16 | EG2: b1 | EH2: b2 | EI2: b3 | EJ2: b4 | EK2: b5 | EL2: b6 | EM2: b7 | EN2: b8 | EO2: b9 | EP2: b10 | EQ2: b11 | ER2: b12 | ES2: b13 | ET2: b14 | EU2: b15 | EV2: b16 | EW2: b17 | EX2: b18 | EY2: b19 | EZ2: b20 | FA2: b21 | FB2: b22 | FC2: b23 | FD2: b24 | FE2: b25 | FF2: b26 | FG2: b27 | FH2: b28 | FI2: b29 | FJ2: b30 | FK2: b31 | FL2: b32 | FM2: b33 | FN2: b34 | FO2: b35 | FP2: b36 | FQ2: b37 | FR2: b38 | FS2: b39 | FT2: b40 | FU2: b41 | FV2: b42 | FW2: b43 | FX2: b44 | FY2: b45 | FZ2: b46 | GA2: b47 | GB2: b48 | GC2: b49 | GD2: b50 | GE2: b51 | GF2: b52 | GG2: b53 | GH2: b54 | GI2: b55 | GJ2: b56 | GK2: b57 | GL2: b58 | GM2: b59 | GN2: b60 | GO2: b61 | GP2: b62 | GQ2: b63 | GR2: b64 | HL2: N1 | HM2: N2 | HN2: N3 | HO2: N4 | HP2: N5 | HQ2: N6 | HR2: N7 | HS2: N8 | HT2: N9 | HU2: N10 | HV2: N11 | HW2: N12 | HX2: N13 | HY2: N14 | HZ2: N15 | IA2: N16 | IC2: b1 | ID2: b2 | IE2: b3 | IF2: b4 | IG2: b5 | IH2: b6 | II2: b7 | IJ2: b8 | IK2: b9 | IL2: b10 | IM2: b11 | IN2: b12 | IO2: b13 | IP2: b14 | IQ2: b15 | IR2: b16 | IS2: b17 | IT2: b18 | IU2: b19 | IV2: b20 | IW2: b21 | IX2: b22 | IY2: b23 | IZ2: b24 | JA2: b25 | JB2: b26 | JC2: b27 | JD2: b28 | JE2: b29 | JF2: b30 | JG2: b31 | JH2: b32 | JI2: b33 | JJ2: b34 | JK2: b35 | JL2: b36 | JM2: b37 | JN2: b38 | JO2: b39 | JP2: b40 | JQ2: b41 | JR2: b42 | JS2: b43 | JT2: b44 | JU2: b45 | JV2: b46 | JW2: b47 | JX2: b48 | JY2: b49 | JZ2: b50 | KA2: b51 | KB2: b52 | KC2: b53 | KD2: b54 | KE2: b55 | KF2: b56 | KG2: b57 | KH2: b58 | KI2: b59 | KJ2: b60 | KK2: b61 | KL2: b62 | KM2: b63 | KN2: b64 | LH2: N1 | LI2: N2 | LJ2: N3 | LK2: N4 | LL2: N5 | LM2: N6 | LN2: N7 | LO2: N8 | LP2: N9 | LQ2: N10 | LR2: N11 | LS2: N12 | LT2: N13 | LU2: N14 | LV2: N15 | LW2: N16 | LY2: b1 | LZ2: b2 | MA2: b3 | MB2: b4 | MC2: b5 | MD2: b6 | ME2: b7 | MF2: b8 | MG2: b9 | MH2: b10 | MI2: b11 | MJ2: b12 | MK2: b13 | ML2: b14 | MM2: b15 | MN2: b16 | MO2: b17 | MP2: b18 | MQ2: b19 | MR2: b20 | MS2: b21 | MT2: b22 | MU2: b23 | MV2: b24 | MW2: b25 | MX2: b26 | MY2: b27 | MZ2: b28 | NA2: b29 | NB2: b30 | NC2: b31 | ND2: b32 | NE2: b33 | NF2: b34 | NG2: b35 | NH2: b36 | NI2: b37 | NJ2: b38 | NK2: b39 | NL2: b40 | NM2: b41 | NN2: b42 | NO2: b43 | NP2: b44 | NQ2: b45 | NR2: b46 | NS2: b47 | NT2: b48 | NU2: b49 | NV2: b50 | NW2: b51 | NX2: b52 | NY2: b53 | NZ2: b54 | OA2: b55 | OB2: b56 | OC2: b57 | OD2: b58 | OE2: b59 | OF2: b60 | OG2: b61 | OH2: b62 | OI2: b63 | OJ2: b64 | OL2: b1 | OM2: b2 | ON2: b3 | OO2: b4 | OP2: b5 | OQ2: b6 | OR2: b7 | OS2: b8 | OT2: b9 | OU2: b10 | OV2: b11 | OW2: b12 | OX2: b13 | OY2: b14 | OZ2: b15 | PA2: b16 | PB2: b17 | PC2: b18 | PD2: b19 | PE2: b20 | PF2: b21 | PG2: b22 | PH2: b23 | PI2: b24 | PJ2: b25 | PK2: b26 | PL2: b27 | PM2: b28 | PN2: b29 | PO2: b30 | PP2: b31 | PQ2: b32 | PR2: b33 | PS2: b34 | PT2: b35 | PU2: b36 | PV2: b37 | PW2: b38 | PX2: b39 | PY2: b40 | PZ2: b41 | QA2: b42 | QB2: b43 | QC2: b44 | QD2: b45 | QE2: b46 | QF2: b47 | QG2: b48 | QH2: b49 | QI2: b50 | QJ2: b51 | QK2: b52 | QL2: b53 | QM2: b54 | QN2: b55 | QO2: b56 | QP2: b57 | QQ2: b58 | QR2: b59 | QS2: b60 | QT2: b61 | QU2: b62 | QV2: b63 | QW2: b64
A3: 123456ABCD132536 | B3: 1 | C3: =MID($A3,1,1) | D3: =MID($A3,2,1) | E3: =MID($A3,3,1) | F3: =MID($A3,4,1) | G3: =MID($A3,5,1) | H3: =MID($A3,6,1) | I3: =MID($A3,7,1) | J3: =MID($A3,8,1) | K3: =MID($A3,9,1) | L3: =MID($A3,10,1) | M3: =MID($A3,11,1) | N3: =MID($A3,12,1) | O3: =MID($A3,13,1) | P3: =MID($A3,14,1) | Q3: =MID($A3,15,1) | R3: =MID($A3,16,1) | T3: =DEC2BIN(HEX2DEC(C3),4) | U3: =DEC2BIN(HEX2DEC(D3),4) | V3: =DEC2BIN(HEX2DEC(E3),4) | W3: =DEC2BIN(HEX2DEC(F3),4) | X3: =DEC2BIN(HEX2DEC(G3),4) | Y3: =DEC2BIN(HEX2DEC(H3),4) | Z3: =DEC2BIN(HEX2DEC(I3),4) | AA3: =DEC2BIN(HEX2DEC(J3),4) | ... AI3: =DEC2BIN(HEX2DEC(R3),4) | AK3: =MID(T3,1,1) | AL3: =MID(T3,2,1) | AM3: =MID(T3,3,1) | AN3: =MID(T3,4,1) | AO3: =MID(U3,1,1) | AP3: =MID(U3,2,1) | AQ3: =MID(U3,3,1) | AR3: =MID(U3,4,1) | AS3: =MID(V3,1,1) | AT3: =MID(V3,2,1) | AU3: =MID(V3,3,1) | AV3: =MID(V3,4,1) | AW3: =MID(W3,1,1) | AX3: =MID(W3,2,1) | AY3: =MID(W3,3,1) | AZ3: =MID(W3,4,1) | BA3: =MID(X3,1,1) | BB3: =MID(X3,2,1) | BC3: =MID(X3,3,1) | BD3: =MID(X3,4,1) | BE3: =MID(Y3,1,1) | BF3: =MID(Y3,2,1) | BG3: =MID(Y3,3,1) | BH3: =MID(Y3,4,1) | BI3: =MID(Z3,1,1) | BJ3: =MID(Z3,2,1) | BK3: =MID(Z3,3,1) | BL3: =MID(Z3,4,1) | BM3: =MID(AA3,1,1) | BN3: =MID(AA3,2,1) | BO3: =MID(AA3,3,1) | BP3: =MID(AA3,4,1) | BQ3: =MID(AB3,1,1) | BR3: =MID(AB3,2,1) | BS3: =MID(AB3,3,1) | BT3: =MID(AB3,4,1) | BU3: =MID(AC3,1,1) | BV3: =MID(AC3,2,1) | BW3: =MID(AC3,3,1) | BX3: =MID(AC3,4,1) | BY3: =MID(AD3,1,1) | BZ3: =MID(AD3,2,1) | CA3: =MID(AD3,3,1) | CB3: =MID(AD3,4,1) | CC3: =MID(AE3,1,1) | CD3: =MID(AE3,2,1) | CE3: =MID(AE3,3,1) | CF3: =MID(AE3,4,1) | CG3: =MID(AF3,1,1) | CH3: =MID(AF3,2,1) | CI3: =MID(AF3,3,1) | CJ3: =MID(AF3,4,1) | CK3: =MID(AG3,1,1) | CL3: =MID(AG3,2,1) | CM3: =MID(AG3,3,1) | CN3: =MID(AG3,4,1) | CO3: =MID(AH3,1,1) | CP3: =MID(AH3,2,1) | CQ3: =MID(AH3,3,1) | CR3: =MID(AH3,4,1) | CS3: =MID(AI3,1,1) | CT3: =MID(AI3,2,1) | CU3: =MID(AI3,3,1) | CV3: =MID(AI3,4,1) | CX3: 923456ABCD132536 | CY3: =MID($CX3,1,1) | CZ3: =MID($CX3,2,1) | DA3: =MID($CX3,3,1) | DB3: =MID($CX3,4,1) | DC3: =MID($CX3,5,1) | DD3: =MID($CX3,6,1) | DE3: =MID($CX3,7,1) | DF3: =MID($CX3,8,1) | DG3: =MID($CX3,9,1) | DH3: =MID($CX3,10,1) | DI3: =MID($CX3,11,1) | DJ3: =MID($CX3,12,1) | DK3: =MID($CX3,13,1) | DL3: =MID($CX3,14,1) | DM3: =MID($CX3,15,1) | DN3: =MID($CX3,16,1) | DP3: =DEC2BIN(HEX2DEC(CY3),4) | DQ3: =DEC2BIN(HEX2DEC(CZ3),4) | DR3: =DEC2BIN(HEX2DEC(DA3),4) | DS3: =DEC2BIN(HEX2DEC(DB3),4) | DT3: =DEC2BIN(HEX2DEC(DC3),4) | DU3: =DEC2BIN(HEX2DEC(DD3),4) | DV3: =DEC2BIN(HEX2DEC(DE3),4) | DW3: =DEC2BIN(HEX2DEC(DF3),4) | ... EE3: =DEC2BIN(HEX2DEC(DN3),4) | EG3: =MID(DP3,1,1) | EH3: =MID(DP3,2,1) | EI3: =MID(DP3,3,1) | EJ3: =MID(DP3,4,1) | EK3: =MID(DQ3,1,1) | EL3: =MID(DQ3,2,1) | EM3: =MID(DQ3,3,1) | EN3: =MID(DQ3,4,1) | EO3: =MID(DR3,1,1) | EP3: =MID(DR3,2,1) | EQ3: =MID(DR3,3,1) | ER3: =MID(DR3,4,1) | ES3: =MID(DS3,1,1) | ET3: =MID(DS3,2,1) | EU3: =MID(DS3,3,1) | EV3: =MID(DS3,4,1) | EW3: =MID(DT3,1,1) | EX3: =MID(DT3,2,1) | EY3: =MID(DT3,3,1) | EZ3: =MID(DT3,4,1) | FA3: =MID(DU3,1,1) | FB3: =MID(DU3,2,1) | FC3: =MID(DU3,3,1) | FD3: =MID(DU3,4,1) | FE3: =MID(DV3,1,1) | FF3: =MID(DV3,2,1) | FG3: =MID(DV3,3,1) | FH3: =MID(DV3,4,1) | FI3: =MID(DW3,1,1) | FJ3: =MID(DW3,2,1) | FK3: =MID(DW3,3,1) | FL3: =MID(DW3,4,1) | FM3: =MID(DX3,1,1) | FN3: =MID(DX3,2,1) | FO3: =MID(DX3,3,1) | FP3: =MID(DX3,4,1) | FQ3: =MID(DY3,1,1) | FR3: =MID(DY3,2,1) | FS3: =MID(DY3,3,1) | FT3: =MID(DY3,4,1) | FU3: =MID(DZ3,1,1) | FV3: =MID(DZ3,2,1) | FW3: =MID(DZ3,3,1) | FX3: =MID(DZ3,4,1) | FY3: =MID(EA3,1,1) | FZ3: =MID(EA3,2,1) | GA3: =MID(EA3,3,1) | GB3: =MID(EA3,4,1) | GC3: =MID(EB3,1,1) | GD3: =MID(EB3,2,1) | GE3: =MID(EB3,3,1) | GF3: =MID(EB3,4,1) | GG3: =MID(EC3,1,1) | GH3: =MID(EC3,2,1) | GI3: =MID(EC3,3,1) | GJ3: =MID(EC3,4,1) | GK3: =MID(ED3,1,1) | GL3: =MID(ED3,2,1) | GM3: =MID(ED3,3,1) | GN3: =MID(ED3,4,1) | GO3: =MID(EE3,1,1) | GP3: =MID(EE3,2,1) | GQ3: =MID(EE3,3,1) | GR3: =MID(EE3,4,1) | GT3: C0B7A8D05F3A829C | GU3: =MID($GT3,1,1) | GV3: =MID($GT3,2,1) | GW3: =MID($GT3,3,1) | GX3: =MID($GT3,4,1) | GY3: =MID($GT3,5,1) | GZ3: =MID($GT3,6,1) | HA3: =MID($GT3,7,1) | HB3: =MID($GT3,8,1) | HC3: =MID($GT3,9,1) | HD3: =MID($GT3,10,1) | HE3: =MID($GT3,11,1) | HF3: =MID($GT3,12,1) | HG3: =MID($GT3,13,1) | HH3: =MID($GT3,14,1) | HI3: =MID($GT3,15,1) | HJ3: =MID($GT3,16,1) | HL3: =DEC2BIN(HEX2DEC(GU3),4) | HM3: =DEC2BIN(HEX2DEC(GV3),4) | HN3: =DEC2BIN(HEX2DEC(GW3),4) | HO3: =DEC2BIN(HEX2DEC(GX3),4) | HP3: =DEC2BIN(HEX2DEC(GY3),4) | HQ3: =DEC2BIN(HEX2DEC(GZ3),4) | HR3: =DEC2BIN(HEX2DEC(HA3),4) | HS3: =DEC2BIN(HEX2DEC(HB3),4) | ... IA3: =DEC2BIN(HEX2DEC(HJ3),4) | IC3: =MID(HL3,1,1) | ID3: =MID(HL3,2,1) | IE3: =MID(HL3,3,1) | IF3: =MID(HL3,4,1) | IG3: =MID(HM3,1,1) | IH3: =MID(HM3,2,1) | II3: =MID(HM3,3,1) | IJ3: =MID(HM3,4,1) | IK3: =MID(HN3,1,1) | IL3: =MID(HN3,2,1) | IM3: =MID(HN3,3,1) | IN3: =MID(HN3,4,1) | IO3: =MID(HO3,1,1) | IP3: =MID(HO3,2,1) | IQ3: =MID(HO3,3,1) | IR3: =MID(HO3,4,1) | IS3: =MID(HP3,1,1) | IT3: =MID(HP3,2,1) | IU3: =MID(HP3,3,1) | IV3: =MID(HP3,4,1) | IW3: =MID(HQ3,1,1) | IX3: =MID(HQ3,2,1) | IY3: =MID(HQ3,3,1) | IZ3: =MID(HQ3,4,1) | JA3: =MID(HR3,1,1) | JB3: =MID(HR3,2,1) | JC3: =MID(HR3,3,1) | JD3: =MID(HR3,4,1) | JE3: =MID(HS3,1,1) | JF3: =MID(HS3,2,1) | JG3: =MID(HS3,3,1) | JH3: =MID(HS3,4,1) | JI3: =MID(HT3,1,1) | JJ3: =MID(HT3,2,1) | JK3: =MID(HT3,3,1) | JL3: =MID(HT3,4,1) | JM3: =MID(HU3,1,1) | JN3: =MID(HU3,2,1) | JO3: =MID(HU3,3,1) | JP3: =MID(HU3,4,1) | JQ3: =MID(HV3,1,1) | JR3: =MID(HV3,2,1) | JS3: =MID(HV3,3,1) | JT3: =MID(HV3,4,1) | JU3: =MID(HW3,1,1) | JV3: =MID(HW3,2,1) | JW3: =MID(HW3,3,1) | JX3: =MID(HW3,4,1) | JY3: =MID(HX3,1,1) | JZ3: =MID(HX3,2,1) | KA3: =MID(HX3,3,1) | KB3: =MID(HX3,4,1) | KC3: =MID(HY3,1,1) | KD3: =MID(HY3,2,1) | KE3: =MID(HY3,3,1) | KF3: =MID(HY3,4,1) | KG3: =MID(HZ3,1,1) | KH3: =MID(HZ3,2,1) | KI3: =MID(HZ3,3,1) | KJ3: =MID(HZ3,4,1) | KK3: =MID(IA3,1,1) | KL3: =MID(IA3,2,1) | KM3: =MID(IA3,3,1) | KN3: =MID(IA3,4,1) | KP3: 89F6EB4779DDA0ED | KQ3: =MID($KP3,1,1) | KR3: =MID($KP3,2,1) | KS3: =MID($KP3,3,1) | KT3: =MID($KP3,4,1) | KU3: =MID($KP3,5,1) | KV3: =MID($KP3,6,1) | KW3: =MID($KP3,7,1) | KX3: =MID($KP3,8,1) | KY3: =MID($KP3,9,1) | KZ3: =MID($KP3,10,1) | LA3: =MID($KP3,11,1) | LB3: =MID($KP3,12,1) | LC3: =MID($KP3,13,1) | LD3: =MID($KP3,14,1) | LE3: =MID($KP3,15,1) | LF3: =MID($KP3,16,1) | LH3: =DEC2BIN(HEX2DEC(KQ3),4) | LI3: =DEC2BIN(HEX2DEC(KR3),4) | LJ3: =DEC2BIN(HEX2DEC(KS3),4) | LK3: =DEC2BIN(HEX2DEC(KT3),4) | LL3: =DEC2BIN(HEX2DEC(KU3),4) | LM3: =DEC2BIN(HEX2DEC(KV3),4) | LN3: =DEC2BIN(HEX2DEC(KW3),4) | LO3: =DEC2BIN(HEX2DEC(KX3),4) | ... LW3: =DEC2BIN(HEX2DEC(LF3),4) | LY3: =MID(LH3,1,1) | LZ3: =MID(LH3,2,1) | MA3: =MID(LH3,3,1) | MB3: =MID(LH3,4,1) | MC3: =MID(LI3,1,1) | MD3: =MID(LI3,2,1) | ME3: =MID(LI3,3,1) | MF3: =MID(LI3,4,1) | MG3: =MID(LJ3,1,1) | MH3: =MID(LJ3,2,1) | MI3: =MID(LJ3,3,1) | MJ3: =MID(LJ3,4,1) | MK3: =MID(LK3,1,1) | ML3: =MID(LK3,2,1) | MM3: =MID(LK3,3,1) | MN3: =MID(LK3,4,1) | MO3: =MID(LL3,1,1) | MP3: =MID(LL3,2,1) | MQ3: =MID(LL3,3,1) | MR3: =MID(LL3,4,1) | MS3: =MID(LM3,1,1) | MT3: =MID(LM3,2,1) | MU3: =MID(LM3,3,1) | MV3: =MID(LM3,4,1) | MW3: =MID(LN3,1,1) | MX3: =MID(LN3,2,1) | MY3: =MID(LN3,3,1) | MZ3: =MID(LN3,4,1) | NA3: =MID(LO3,1,1) | NB3: =MID(LO3,2,1) | NC3: =MID(LO3,3,1) | ND3: =MID(LO3,4,1) | NE3: =MID(LP3,1,1) | NF3: =MID(LP3,2,1) | NG3: =MID(LP3,3,1) | NH3: =MID(LP3,4,1) | NI3: =MID(LQ3,1,1) | NJ3: =MID(LQ3,2,1) | NK3: =MID(LQ3,3,1) | NL3: =MID(LQ3,4,1) | NM3: =MID(LR3,1,1) | NN3: =MID(LR3,2,1) | NO3: =MID(LR3,3,1) | NP3: =MID(LR3,4,1) | NQ3: =MID(LS3,1,1) | NR3: =MID(LS3,2,1) | NS3: =MID(LS3,3,1) | NT3: =MID(LS3,4,1) | NU3: =MID(LT3,1,1) | NV3: =MID(LT3,2,1) | NW3: =MID(LT3,3,1) | NX3: =MID(LT3,4,1) | NY3: =MID(LU3,1,1) | NZ3: =MID(LU3,2,1) | OA3: =MID(LU3,3,1) | OB3: =MID(LU3,4,1) | OC3: =MID(LV3,1,1) | OD3: =MID(LV3,2,1) | OE3: =MID(LV3,3,1) | OF3: =MID(LV3,4,1) | OG3: =MID(LW3,1,1) | OH3: =MID(LW3,2,1) | OI3: =MID(LW3,3,1) | OJ3: =MID(LW3,4,1) | OL3: =MOD(IC3+LY3,2) | OM3: =MOD(ID3+LZ3,2) | ON3: =MOD(IE3+MA3,2) | OO3: =MOD(IF3+MB3,2) | OP3: =MOD(IG3+MC3,2) | OQ3: =MOD(IH3+MD3,2) | OR3: =MOD(II3+ME3,2) | OS3: =MOD(IJ3+MF3,2) | ... QW3: =MOD(KN3+OJ3,2) | QY3: =SUM(OL3:QW3)
A4: 123456ABCD132536 | B4: 2 | C4: =MID($A4,1,1) | D4: =MID($A4,2,1) | E4: =MID($A4,3,1) | F4: =MID($A4,4,1) | G4: =MID($A4,5,1) | H4: =MID($A4,6,1) | I4: =MID($A4,7,1) | J4: =MID($A4,8,1) | K4: =MID($A4,9,1) | L4: =MID($A4,10,1) | M4: =MID($A4,11,1) | N4: =MID($A4,12,1) | O4: =MID($A4,13,1) | P4: =MID($A4,14,1) | Q4: =MID($A4,15,1) | R4: =MID($A4,16,1) | T4: =DEC2BIN(HEX2DEC(C4),4) | U4: =DEC2BIN(HEX2DEC(D4),4) | V4: =DEC2BIN(HEX2DEC(E4),4) | W4: =DEC2BIN(HEX2DEC(F4),4) | X4: =DEC2BIN(HEX2DEC(G4),4) | Y4: =DEC2BIN(HEX2DEC(H4),4) | Z4: =DEC2BIN(HEX2DEC(I4),4) | AA4: =DEC2BIN(HEX2DEC(J4),4) | ... AI4: =DEC2BIN(HEX2DEC(R4),4) | AK4: =MID(T4,1,1) | AL4: =MID(T4,2,1) | AM4: =MID(T4,3,1) | AN4: =MID(T4,4,1) | AO4: =MID(U4,1,1) | AP4: =MID(U4,2,1) | AQ4: =MID(U4,3,1) | AR4: =MID(U4,4,1) | AS4: =MID(V4,1,1) | AT4: =MID(V4,2,1) | AU4: =MID(V4,3,1) | AV4: =MID(V4,4,1) | AW4: =MID(W4,1,1) | AX4: =MID(W4,2,1) | AY4: =MID(W4,3,1) | AZ4: =MID(W4,4,1) | BA4: =MID(X4,1,1) | BB4: =MID(X4,2,1) | BC4: =MID(X4,3,1) | BD4: =MID(X4,4,1) | BE4: =MID(Y4,1,1) | BF4: =MID(Y4,2,1) | BG4: =MID(Y4,3,1) | BH4: =MID(Y4,4,1) | BI4: =MID(Z4,1,1) | BJ4: =MID(Z4,2,1) | BK4: =MID(Z4,3,1) | BL4: =MID(Z4,4,1) | BM4: =MID(AA4,1,1) | BN4: =MID(AA4,2,1) | BO4: =MID(AA4,3,1) | BP4: =MID(AA4,4,1) | BQ4: =MID(AB4,1,1) | BR4: =MID(AB4,2,1) | BS4: =MID(AB4,3,1) | BT4: =MID(AB4,4,1) | BU4: =MID(AC4,1,1) | BV4: =MID(AC4,2,1) | BW4: =MID(AC4,3,1) | BX4: =MID(AC4,4,1) | BY4: =MID(AD4,1,1) | BZ4: =MID(AD4,2,1) | CA4: =MID(AD4,3,1) | CB4: =MID(AD4,4,1) | CC4: =MID(AE4,1,1) | CD4: =MID(AE4,2,1) | CE4: =MID(AE4,3,1) | CF4: =MID(AE4,4,1) | CG4: =MID(AF4,1,1) | CH4: =MID(AF4,2,1) | CI4: =MID(AF4,3,1) | CJ4: =MID(AF4,4,1) | CK4: =MID(AG4,1,1) | CL4: =MID(AG4,2,1) | CM4: =MID(AG4,3,1) | CN4: =MID(AG4,4,1) | CO4: =MID(AH4,1,1) | CP4: =MID(AH4,2,1) | CQ4: =MID(AH4,3,1) | CR4: =MID(AH4,4,1) | CS4: =MID(AI4,1,1) | CT4: =MID(AI4,2,1) | CU4: =MID(AI4,3,1) | CV4: =MID(AI4,4,1) | CX4: 523456ABCD132536 | CY4: =MID($CX4,1,1) | CZ4: =MID($CX4,2,1) | DA4: =MID($CX4,3,1) | DB4: =MID($CX4,4,1) | DC4: =MID($CX4,5,1) | DD4: =MID($CX4,6,1) | DE4: =MID($CX4,7,1) | DF4: =MID($CX4,8,1) | DG4: =MID($CX4,9,1) | DH4: =MID($CX4,10,1) | DI4: =MID($CX4,11,1) | DJ4: =MID($CX4,12,1) | DK4: =MID($CX4,13,1) | DL4: =MID($CX4,14,1) | DM4: =MID($CX4,15,1) | DN4: =MID($CX4,16,1) | DP4: =DEC2BIN(HEX2DEC(CY4),4) | DQ4: =DEC2BIN(HEX2DEC(CZ4),4) | DR4: =DEC2BIN(HEX2DEC(DA4),4) | DS4: =DEC2BIN(HEX2DEC(DB4),4) | DT4: =DEC2BIN(HEX2DEC(DC4),4) | DU4: =DEC2BIN(HEX2DEC(DD4),4) | DV4: =DEC2BIN(HEX2DEC(DE4),4) | DW4: =DEC2BIN(HEX2DEC(DF4),4) | ... EE4: =DEC2BIN(HEX2DEC(DN4),4) | EG4: =MID(DP4,1,1) | EH4: =MID(DP4,2,1) | EI4: =MID(DP4,3,1) | EJ4: =MID(DP4,4,1) | EK4: =MID(DQ4,1,1) | EL4: =MID(DQ4,2,1) | EM4: =MID(DQ4,3,1) | EN4: =MID(DQ4,4,1) | EO4: =MID(DR4,1,1) | EP4: =MID(DR4,2,1) | EQ4: =MID(DR4,3,1) | ER4: =MID(DR4,4,1) | ES4: =MID(DS4,1,1) | ET4: =MID(DS4,2,1) | EU4: =MID(DS4,3,1) | EV4: =MID(DS4,4,1) | EW4: =MID(DT4,1,1) | EX4: =MID(DT4,2,1) | EY4: =MID(DT4,3,1) | EZ4: =MID(DT4,4,1) | FA4: =MID(DU4,1,1) | FB4: =MID(DU4,2,1) | FC4: =MID(DU4,3,1) | FD4: =MID(DU4,4,1) | FE4: =MID(DV4,1,1) | FF4: =MID(DV4,2,1) | FG4: =MID(DV4,3,1) | FH4: =MID(DV4,4,1) | FI4: =MID(DW4,1,1) | FJ4: =MID(DW4,2,1) | FK4: =MID(DW4,3,1) | FL4: =MID(DW4,4,1) | FM4: =MID(DX4,1,1) | FN4: =MID(DX4,2,1) | FO4: =MID(DX4,3,1) | FP4: =MID(DX4,4,1) | FQ4: =MID(DY4,1,1) | FR4: =MID(DY4,2,1) | FS4: =MID(DY4,3,1) | FT4: =MID(DY4,4,1) | FU4: =MID(DZ4,1,1) | FV4: =MID(DZ4,2,1) | FW4: =MID(DZ4,3,1) | FX4: =MID(DZ4,4,1) | FY4: =MID(EA4,1,1) | FZ4: =MID(EA4,2,1) | GA4: =MID(EA4,3,1) | GB4: =MID(EA4,4,1) | GC4: =MID(EB4,1,1) | GD4: =MID(EB4,2,1) | GE4: =MID(EB4,3,1) | GF4: =MID(EB4,4,1) | GG4: =MID(EC4,1,1) | GH4: =MID(EC4,2,1) | GI4: =MID(EC4,3,1) | GJ4: =MID(EC4,4,1) | GK4: =MID(ED4,1,1) | GL4: =MID(ED4,2,1) | GM4: =MID(ED4,3,1) | GN4: =MID(ED4,4,1) | GO4: =MID(EE4,1,1) | GP4: =MID(EE4,2,1) | GQ4: =MID(EE4,3,1) | GR4: =MID(EE4,4,1) | GT4: C0B7A8D05F3A829C | GU4: =MID($GT4,1,1) | GV4: =MID($GT4,2,1) | GW4: =MID($GT4,3,1) | GX4: =MID($GT4,4,1) | GY4: =MID($GT4,5,1) | GZ4: =MID($GT4,6,1) | HA4: =MID($GT4,7,1) | HB4: =MID($GT4,8,1) | HC4: =MID($GT4,9,1) | HD4: =MID($GT4,10,1) | HE4: =MID($GT4,11,1) | HF4: =MID($GT4,12,1) | HG4: =MID($GT4,13,1) | HH4: =MID($GT4,14,1) | HI4: =MID($GT4,15,1) | HJ4: =MID($GT4,16,1) | HL4: =DEC2BIN(HEX2DEC(GU4),4) | HM4: =DEC2BIN(HEX2DEC(GV4),4) | HN4: =DEC2BIN(HEX2DEC(GW4),4) | HO4: =DEC2BIN(HEX2DEC(GX4),4) | HP4: =DEC2BIN(HEX2DEC(GY4),4) | HQ4: =DEC2BIN(HEX2DEC(GZ4),4) | HR4: =DEC2BIN(HEX2DEC(HA4),4) | HS4: =DEC2BIN(HEX2DEC(HB4),4) | ... IA4: =DEC2BIN(HEX2DEC(HJ4),4) | IC4: =MID(HL4,1,1) | ID4: =MID(HL4,2,1) | IE4: =MID(HL4,3,1) | IF4: =MID(HL4,4,1) | IG4: =MID(HM4,1,1) | IH4: =MID(HM4,2,1) | II4: =MID(HM4,3,1) | IJ4: =MID(HM4,4,1) | IK4: =MID(HN4,1,1) | IL4: =MID(HN4,2,1) | IM4: =MID(HN4,3,1) | IN4: =MID(HN4,4,1) | IO4: =MID(HO4,1,1) | IP4: =MID(HO4,2,1) | IQ4: =MID(HO4,3,1) | IR4: =MID(HO4,4,1) | IS4: =MID(HP4,1,1) | IT4: =MID(HP4,2,1) | IU4: =MID(HP4,3,1) | IV4: =MID(HP4,4,1) | IW4: =MID(HQ4,1,1) | IX4: =MID(HQ4,2,1) | IY4: =MID(HQ4,3,1) | IZ4: =MID(HQ4,4,1) | JA4: =MID(HR4,1,1) | JB4: =MID(HR4,2,1) | JC4: =MID(HR4,3,1) | JD4: =MID(HR4,4,1) | JE4: =MID(HS4,1,1) | JF4: =MID(HS4,2,1) | JG4: =MID(HS4,3,1) | JH4: =MID(HS4,4,1) | JI4: =MID(HT4,1,1) | JJ4: =MID(HT4,2,1) | JK4: =MID(HT4,3,1) | JL4: =MID(HT4,4,1) | JM4: =MID(HU4,1,1) | JN4: =MID(HU4,2,1) | JO4: =MID(HU4,3,1) | JP4: =MID(HU4,4,1) | JQ4: =MID(HV4,1,1) | JR4: =MID(HV4,2,1) | JS4: =MID(HV4,3,1) | JT4: =MID(HV4,4,1) | JU4: =MID(HW4,1,1) | JV4: =MID(HW4,2,1) | JW4: =MID(HW4,3,1) | JX4: =MID(HW4,4,1) | JY4: =MID(HX4,1,1) | JZ4: =MID(HX4,2,1) | KA4: =MID(HX4,3,1) | KB4: =MID(HX4,4,1) | KC4: =MID(HY4,1,1) | KD4: =MID(HY4,2,1) | KE4: =MID(HY4,3,1) | KF4: =MID(HY4,4,1) | KG4: =MID(HZ4,1,1) | KH4: =MID(HZ4,2,1) | KI4: =MID(HZ4,3,1) | KJ4: =MID(HZ4,4,1) | KK4: =MID(IA4,1,1) | KL4: =MID(IA4,2,1) | KM4: =MID(IA4,3,1) | KN4: =MID(IA4,4,1) | KP4: 6B05C199BD5C7573 | KQ4: =MID($KP4,1,1) | KR4: =MID($KP4,2,1) | KS4: =MID($KP4,3,1) | KT4: =MID($KP4,4,1) | KU4: =MID($KP4,5,1) | KV4: =MID($KP4,6,1) | KW4: =MID($KP4,7,1) | KX4: =MID($KP4,8,1) | KY4: =MID($KP4,9,1) | KZ4: =MID($KP4,10,1) | LA4: =MID($KP4,11,1) | LB4: =MID($KP4,12,1) | LC4: =MID($KP4,13,1) | LD4: =MID($KP4,14,1) | LE4: =MID($KP4,15,1) | LF4: =MID($KP4,16,1) | LH4: =DEC2BIN(HEX2DEC(KQ4),4) | LI4: =DEC2BIN(HEX2DEC(KR4),4) | LJ4: =DEC2BIN(HEX2DEC(KS4),4) | LK4: =DEC2BIN(HEX2DEC(KT4),4) | LL4: =DEC2BIN(HEX2DEC(KU4),4) | LM4: =DEC2BIN(HEX2DEC(KV4),4) | LN4: =DEC2BIN(HEX2DEC(KW4),4) | LO4: =DEC2BIN(HEX2DEC(KX4),4) | ... LW4: =DEC2BIN(HEX2DEC(LF4),4) | LY4: =MID(LH4,1,1) | LZ4: =MID(LH4,2,1) | MA4: =MID(LH4,3,1) | MB4: =MID(LH4,4,1) | MC4: =MID(LI4,1,1) | MD4: =MID(LI4,2,1) | ME4: =MID(LI4,3,1) | MF4: =MID(LI4,4,1) | MG4: =MID(LJ4,1,1) | MH4: =MID(LJ4,2,1) | MI4: =MID(LJ4,3,1) | MJ4: =MID(LJ4,4,1) | MK4: =MID(LK4,1,1) | ML4: =MID(LK4,2,1) | MM4: =MID(LK4,3,1) | MN4: =MID(LK4,4,1) | MO4: =MID(LL4,1,1) | MP4: =MID(LL4,2,1) | MQ4: =MID(LL4,3,1) | MR4: =MID(LL4,4,1) | MS4: =MID(LM4,1,1) | MT4: =MID(LM4,2,1) | MU4: =MID(LM4,3,1) | MV4: =MID(LM4,4,1) | MW4: =MID(LN4,1,1) | MX4: =MID(LN4,2,1) | MY4: =MID(LN4,3,1) | MZ4: =MID(LN4,4,1) | NA4: =MID(LO4,1,1) | NB4: =MID(LO4,2,1) | NC4: =MID(LO4,3,1) | ND4: =MID(LO4,4,1) | NE4: =MID(LP4,1,1) | NF4: =MID(LP4,2,1) | NG4: =MID(LP4,3,1) | NH4: =MID(LP4,4,1) | NI4: =MID(LQ4,1,1) | NJ4: =MID(LQ4,2,1) | NK4: =MID(LQ4,3,1) | NL4: =MID(LQ4,4,1) | NM4: =MID(LR4,1,1) | NN4: =MID(LR4,2,1) | NO4: =MID(LR4,3,1) | NP4: =MID(LR4,4,1) | NQ4: =MID(LS4,1,1) | NR4: =MID(LS4,2,1) | NS4: =MID(LS4,3,1) | NT4: =MID(LS4,4,1) | NU4: =MID(LT4,1,1) | NV4: =MID(LT4,2,1) | NW4: =MID(LT4,3,1) | NX4: =MID(LT4,4,1) | NY4: =MID(LU4,1,1) | NZ4: =MID(LU4,2,1) | OA4: =MID(LU4,3,1) | OB4: =MID(LU4,4,1) | OC4: =MID(LV4,1,1) | OD4: =MID(LV4,2,1) | OE4: =MID(LV4,3,1) | OF4: =MID(LV4,4,1) | OG4: =MID(LW4,1,1) | OH4: =MID(LW4,2,1) | OI4: =MID(LW4,3,1) | OJ4: =MID(LW4,4,1) | OL4: =MOD(IC4+LY4,2) | OM4: =MOD(ID4+LZ4,2) | ON4: =MOD(IE4+MA4,2) | OO4: =MOD(IF4+MB4,2) | OP4: =MOD(IG4+MC4,2) | OQ4: =MOD(IH4+MD4,2) | OR4: =MOD(II4+ME4,2) | OS4: =MOD(IJ4+MF4,2) | ... QW4: =MOD(KN4+OJ4,2) | QY4: =SUM(OL4:QW4)
A5: 123456ABCD132536 | B5: 3 | C5: =MID($A5,1,1) | D5: =MID($A5,2,1) | E5: =MID($A5,3,1) | F5: =MID($A5,4,1) | G5: =MID($A5,5,1) | H5: =MID($A5,6,1) | I5: =MID($A5,7,1) | J5: =MID($A5,8,1) | K5: =MID($A5,9,1) | L5: =MID($A5,10,1) | M5: =MID($A5,11,1) | N5: =MID($A5,12,1) | O5: =MID($A5,13,1) | P5: =MID($A5,14,1) | Q5: =MID($A5,15,1) | R5: =MID($A5,16,1) | T5: =DEC2BIN(HEX2DEC(C5),4) | U5: =DEC2BIN(HEX2DEC(D5),4) | V5: =DEC2BIN(HEX2DEC(E5),4) | W5: =DEC2BIN(HEX2DEC(F5),4) | X5: =DEC2BIN(HEX2DEC(G5),4) | Y5: =DEC2BIN(HEX2DEC(H5),4) | Z5: =DEC2BIN(HEX2DEC(I5),4) | AA5: =DEC2BIN(HEX2DEC(J5),4) | ... AI5: =DEC2BIN(HEX2DEC(R5),4) | AK5: =MID(T5,1,1) | AL5: =MID(T5,2,1) | AM5: =MID(T5,3,1) | AN5: =MID(T5,4,1) | AO5: =MID(U5,1,1) | AP5: =MID(U5,2,1) | AQ5: =MID(U5,3,1) | AR5: =MID(U5,4,1) | AS5: =MID(V5,1,1) | AT5: =MID(V5,2,1) | AU5: =MID(V5,3,1) | AV5: =MID(V5,4,1) | AW5: =MID(W5,1,1) | AX5: =MID(W5,2,1) | AY5: =MID(W5,3,1) | AZ5: =MID(W5,4,1) | BA5: =MID(X5,1,1) | BB5: =MID(X5,2,1) | BC5: =MID(X5,3,1) | BD5: =MID(X5,4,1) | BE5: =MID(Y5,1,1) | BF5: =MID(Y5,2,1) | BG5: =MID(Y5,3,1) | BH5: =MID(Y5,4,1) | BI5: =MID(Z5,1,1) | BJ5: =MID(Z5,2,1) | BK5: =MID(Z5,3,1) | BL5: =MID(Z5,4,1) | BM5: =MID(AA5,1,1) | BN5: =MID(AA5,2,1) | BO5: =MID(AA5,3,1) | BP5: =MID(AA5,4,1) | BQ5: =MID(AB5,1,1) | BR5: =MID(AB5,2,1) | BS5: =MID(AB5,3,1) | BT5: =MID(AB5,4,1) | BU5: =MID(AC5,1,1) | BV5: =MID(AC5,2,1) | BW5: =MID(AC5,3,1) | BX5: =MID(AC5,4,1) | BY5: =MID(AD5,1,1) | BZ5: =MID(AD5,2,1) | CA5: =MID(AD5,3,1) | CB5: =MID(AD5,4,1) | CC5: =MID(AE5,1,1) | CD5: =MID(AE5,2,1) | CE5: =MID(AE5,3,1) | CF5: =MID(AE5,4,1) | CG5: =MID(AF5,1,1) | CH5: =MID(AF5,2,1) | CI5: =MID(AF5,3,1) | CJ5: =MID(AF5,4,1) | CK5: =MID(AG5,1,1) | CL5: =MID(AG5,2,1) | CM5: =MID(AG5,3,1) | CN5: =MID(AG5,4,1) | CO5: =MID(AH5,1,1) | CP5: =MID(AH5,2,1) | CQ5: =MID(AH5,3,1) | CR5: =MID(AH5,4,1) | CS5: =MID(AI5,1,1) | CT5: =MID(AI5,2,1) | CU5: =MID(AI5,3,1) | CV5: =MID(AI5,4,1) | CX5: 323456ABCD132536 | CY5: =MID($CX5,1,1) | CZ5: =MID($CX5,2,1) | DA5: =MID($CX5,3,1) | DB5: =MID($CX5,4,1) | DC5: =MID($CX5,5,1) | DD5: =MID($CX5,6,1) | DE5: =MID($CX5,7,1) | DF5: =MID($CX5,8,1) | DG5: =MID($CX5,9,1) | DH5: =MID($CX5,10,1) | DI5: =MID($CX5,11,1) | DJ5: =MID($CX5,12,1) | DK5: =MID($CX5,13,1) | DL5: =MID($CX5,14,1) | DM5: =MID($CX5,15,1) | DN5: =MID($CX5,16,1) | DP5: =DEC2BIN(HEX2DEC(CY5),4) | DQ5: =DEC2BIN(HEX2DEC(CZ5),4) | DR5: =DEC2BIN(HEX2DEC(DA5),4) | DS5: =DEC2BIN(HEX2DEC(DB5),4) | DT5: =DEC2BIN(HEX2DEC(DC5),4) | DU5: =DEC2BIN(HEX2DEC(DD5),4) | DV5: =DEC2BIN(HEX2DEC(DE5),4) | DW5: =DEC2BIN(HEX2DEC(DF5),4) | ... EE5: =DEC2BIN(HEX2DEC(DN5),4) | EG5: =MID(DP5,1,1) | EH5: =MID(DP5,2,1) | EI5: =MID(DP5,3,1) | EJ5: =MID(DP5,4,1) | EK5: =MID(DQ5,1,1) | EL5: =MID(DQ5,2,1) | EM5: =MID(DQ5,3,1) | EN5: =MID(DQ5,4,1) | EO5: =MID(DR5,1,1) | EP5: =MID(DR5,2,1) | EQ5: =MID(DR5,3,1) | ER5: =MID(DR5,4,1) | ES5: =MID(DS5,1,1) | ET5: =MID(DS5,2,1) | EU5: =MID(DS5,3,1) | EV5: =MID(DS5,4,1) | EW5: =MID(DT5,1,1) | EX5: =MID(DT5,2,1) | EY5: =MID(DT5,3,1) | EZ5: =MID(DT5,4,1) | FA5: =MID(DU5,1,1) | FB5: =MID(DU5,2,1) | FC5: =MID(DU5,3,1) | FD5: =MID(DU5,4,1) | FE5: =MID(DV5,1,1) | FF5: =MID(DV5,2,1) | FG5: =MID(DV5,3,1) | FH5: =MID(DV5,4,1) | FI5: =MID(DW5,1,1) | FJ5: =MID(DW5,2,1) | FK5: =MID(DW5,3,1) | FL5: =MID(DW5,4,1) | FM5: =MID(DX5,1,1) | FN5: =MID(DX5,2,1) | FO5: =MID(DX5,3,1) | FP5: =MID(DX5,4,1) | FQ5: =MID(DY5,1,1) | FR5: =MID(DY5,2,1) | FS5: =MID(DY5,3,1) | FT5: =MID(DY5,4,1) | FU5: =MID(DZ5,1,1) | FV5: =MID(DZ5,2,1) | FW5: =MID(DZ5,3,1) | FX5: =MID(DZ5,4,1) | FY5: =MID(EA5,1,1) | FZ5: =MID(EA5,2,1) | GA5: =MID(EA5,3,1) | GB5: =MID(EA5,4,1) | GC5: =MID(EB5,1,1) | GD5: =MID(EB5,2,1) | GE5: =MID(EB5,3,1) | GF5: =MID(EB5,4,1) | GG5: =MID(EC5,1,1) | GH5: =MID(EC5,2,1) | GI5: =MID(EC5,3,1) | GJ5: =MID(EC5,4,1) | GK5: =MID(ED5,1,1) | GL5: =MID(ED5,2,1) | GM5: =MID(ED5,3,1) | GN5: =MID(ED5,4,1) | GO5: =MID(EE5,1,1) | GP5: =MID(EE5,2,1) | GQ5: =MID(EE5,3,1) | GR5: =MID(EE5,4,1) | GT5: C0B7A8D05F3A829C | GU5: =MID($GT5,1,1) | GV5: =MID($GT5,2,1) | GW5: =MID($GT5,3,1) | GX5: =MID($GT5,4,1) | GY5: =MID($GT5,5,1) | GZ5: =MID($GT5,6,1) | HA5: =MID($GT5,7,1) | HB5: =MID($GT5,8,1) | HC5: =MID($GT5,9,1) | HD5: =MID($GT5,10,1) | HE5: =MID($GT5,11,1) | HF5: =MID($GT5,12,1) | HG5: =MID($GT5,13,1) | HH5: =MID($GT5,14,1) | HI5: =MID($GT5,15,1) | HJ5: =MID($GT5,16,1) | HL5: =DEC2BIN(HEX2DEC(GU5),4) | HM5: =DEC2BIN(HEX2DEC(GV5),4) | HN5: =DEC2BIN(HEX2DEC(GW5),4) | HO5: =DEC2BIN(HEX2DEC(GX5),4) | HP5: =DEC2BIN(HEX2DEC(GY5),4) | HQ5: =DEC2BIN(HEX2DEC(GZ5),4) | HR5: =DEC2BIN(HEX2DEC(HA5),4) | HS5: =DEC2BIN(HEX2DEC(HB5),4) | ... IA5: =DEC2BIN(HEX2DEC(HJ5),4) | IC5: =MID(HL5,1,1) | ID5: =MID(HL5,2,1) | IE5: =MID(HL5,3,1) | IF5: =MID(HL5,4,1) | IG5: =MID(HM5,1,1) | IH5: =MID(HM5,2,1) | II5: =MID(HM5,3,1) | IJ5: =MID(HM5,4,1) | IK5: =MID(HN5,1,1) | IL5: =MID(HN5,2,1) | IM5: =MID(HN5,3,1) | IN5: =MID(HN5,4,1) | IO5: =MID(HO5,1,1) | IP5: =MID(HO5,2,1) | IQ5: =MID(HO5,3,1) | IR5: =MID(HO5,4,1) | IS5: =MID(HP5,1,1) | IT5: =MID(HP5,2,1) | IU5: =MID(HP5,3,1) | IV5: =MID(HP5,4,1) | IW5: =MID(HQ5,1,1) | IX5: =MID(HQ5,2,1) | IY5: =MID(HQ5,3,1) | IZ5: =MID(HQ5,4,1) | JA5: =MID(HR5,1,1) | JB5: =MID(HR5,2,1) | JC5: =MID(HR5,3,1) | JD5: =MID(HR5,4,1) | JE5: =MID(HS5,1,1) | JF5: =MID(HS5,2,1) | JG5: =MID(HS5,3,1) | JH5: =MID(HS5,4,1) | JI5: =MID(HT5,1,1) | JJ5: =MID(HT5,2,1) | JK5: =MID(HT5,3,1) | JL5: =MID(HT5,4,1) | JM5: =MID(HU5,1,1) | JN5: =MID(HU5,2,1) | JO5: =MID(HU5,3,1) | JP5: =MID(HU5,4,1) | JQ5: =MID(HV5,1,1) | JR5: =MID(HV5,2,1) | JS5: =MID(HV5,3,1) | JT5: =MID(HV5,4,1) | JU5: =MID(HW5,1,1) | JV5: =MID(HW5,2,1) | JW5: =MID(HW5,3,1) | JX5: =MID(HW5,4,1) | JY5: =MID(HX5,1,1) | JZ5: =MID(HX5,2,1) | KA5: =MID(HX5,3,1) | KB5: =MID(HX5,4,1) | KC5: =MID(HY5,1,1) | KD5: =MID(HY5,2,1) | KE5: =MID(HY5,3,1) | KF5: =MID(HY5,4,1) | KG5: =MID(HZ5,1,1) | KH5: =MID(HZ5,2,1) | KI5: =MID(HZ5,3,1) | KJ5: =MID(HZ5,4,1) | KK5: =MID(IA5,1,1) | KL5: =MID(IA5,2,1) | KM5: =MID(IA5,3,1) | KN5: =MID(IA5,4,1) | KP5: F8F454B94CCAF8B6 | KQ5: =MID($KP5,1,1) | KR5: =MID($KP5,2,1) | KS5: =MID($KP5,3,1) | KT5: =MID($KP5,4,1) | KU5: =MID($KP5,5,1) | KV5: =MID($KP5,6,1) | KW5: =MID($KP5,7,1) | KX5: =MID($KP5,8,1) | KY5: =MID($KP5,9,1) | KZ5: =MID($KP5,10,1) | LA5: =MID($KP5,11,1) | LB5: =MID($KP5,12,1) | LC5: =MID($KP5,13,1) | LD5: =MID($KP5,14,1) | LE5: =MID($KP5,15,1) | LF5: =MID($KP5,16,1) | LH5: =DEC2BIN(HEX2DEC(KQ5),4) | LI5: =DEC2BIN(HEX2DEC(KR5),4) | LJ5: =DEC2BIN(HEX2DEC(KS5),4) | LK5: =DEC2BIN(HEX2DEC(KT5),4) | LL5: =DEC2BIN(HEX2DEC(KU5),4) | LM5: =DEC2BIN(HEX2DEC(KV5),4) | LN5: =DEC2BIN(HEX2DEC(KW5),4) | LO5: =DEC2BIN(HEX2DEC(KX5),4) | ... LW5: =DEC2BIN(HEX2DEC(LF5),4) | LY5: =MID(LH5,1,1) | LZ5: =MID(LH5,2,1) | MA5: =MID(LH5,3,1) | MB5: =MID(LH5,4,1) | MC5: =MID(LI5,1,1) | MD5: =MID(LI5,2,1) | ME5: =MID(LI5,3,1) | MF5: =MID(LI5,4,1) | MG5: =MID(LJ5,1,1) | MH5: =MID(LJ5,2,1) | MI5: =MID(LJ5,3,1) | MJ5: =MID(LJ5,4,1) | MK5: =MID(LK5,1,1) | ML5: =MID(LK5,2,1) | MM5: =MID(LK5,3,1) | MN5: =MID(LK5,4,1) | MO5: =MID(LL5,1,1) | MP5: =MID(LL5,2,1) | MQ5: =MID(LL5,3,1) | MR5: =MID(LL5,4,1) | MS5: =MID(LM5,1,1) | MT5: =MID(LM5,2,1) | MU5: =MID(LM5,3,1) | MV5: =MID(LM5,4,1) | MW5: =MID(LN5,1,1) | MX5: =MID(LN5,2,1) | MY5: =MID(LN5,3,1) | MZ5: =MID(LN5,4,1) | NA5: =MID(LO5,1,1) | NB5: =MID(LO5,2,1) | NC5: =MID(LO5,3,1) | ND5: =MID(LO5,4,1) | NE5: =MID(LP5,1,1) | NF5: =MID(LP5,2,1) | NG5: =MID(LP5,3,1) | NH5: =MID(LP5,4,1) | NI5: =MID(LQ5,1,1) | NJ5: =MID(LQ5,2,1) | NK5: =MID(LQ5,3,1) | NL5: =MID(LQ5,4,1) | NM5: =MID(LR5,1,1) | NN5: =MID(LR5,2,1) | NO5: =MID(LR5,3,1) | NP5: =MID(LR5,4,1) | NQ5: =MID(LS5,1,1) | NR5: =MID(LS5,2,1) | NS5: =MID(LS5,3,1) | NT5: =MID(LS5,4,1) | NU5: =MID(LT5,1,1) | NV5: =MID(LT5,2,1) | NW5: =MID(LT5,3,1) | NX5: =MID(LT5,4,1) | NY5: =MID(LU5,1,1) | NZ5: =MID(LU5,2,1) | OA5: =MID(LU5,3,1) | OB5: =MID(LU5,4,1) | OC5: =MID(LV5,1,1) | OD5: =MID(LV5,2,1) | OE5: =MID(LV5,3,1) | OF5: =MID(LV5,4,1) | OG5: =MID(LW5,1,1) | OH5: =MID(LW5,2,1) | OI5: =MID(LW5,3,1) | OJ5: =MID(LW5,4,1) | OL5: =MOD(IC5+LY5,2) | OM5: =MOD(ID5+LZ5,2) | ON5: =MOD(IE5+MA5,2) | OO5: =MOD(IF5+MB5,2) | OP5: =MOD(IG5+MC5,2) | OQ5: =MOD(IH5+MD5,2) | OR5: =MOD(II5+ME5,2) | OS5: =MOD(IJ5+MF5,2) | ... QW5: =MOD(KN5+OJ5,2) | QY5: =SUM(OL5:QW5)
A6: 123456ABCD132536 | B6: 4 | C6: =MID($A6,1,1) | D6: =MID($A6,2,1) | E6: =MID($A6,3,1) | F6: =MID($A6,4,1) | G6: =MID($A6,5,1) | H6: =MID($A6,6,1) | I6: =MID($A6,7,1) | J6: =MID($A6,8,1) | K6: =MID($A6,9,1) | L6: =MID($A6,10,1) | M6: =MID($A6,11,1) | N6: =MID($A6,12,1) | O6: =MID($A6,13,1) | P6: =MID($A6,14,1) | Q6: =MID($A6,15,1) | R6: =MID($A6,16,1) | T6: =DEC2BIN(HEX2DEC(C6),4) | U6: =DEC2BIN(HEX2DEC(D6),4) | V6: =DEC2BIN(HEX2DEC(E6),4) | W6: =DEC2BIN(HEX2DEC(F6),4) | X6: =DEC2BIN(HEX2DEC(G6),4) | Y6: =DEC2BIN(HEX2DEC(H6),4) | Z6: =DEC2BIN(HEX2DEC(I6),4) | AA6: =DEC2BIN(HEX2DEC(J6),4) | ... AI6: =DEC2BIN(HEX2DEC(R6),4) | AK6: =MID(T6,1,1) | AL6: =MID(T6,2,1) | AM6: =MID(T6,3,1) | AN6: =MID(T6,4,1) | AO6: =MID(U6,1,1) | AP6: =MID(U6,2,1) | AQ6: =MID(U6,3,1) | AR6: =MID(U6,4,1) | AS6: =MID(V6,1,1) | AT6: =MID(V6,2,1) | AU6: =MID(V6,3,1) | AV6: =MID(V6,4,1) | AW6: =MID(W6,1,1) | AX6: =MID(W6,2,1) | AY6: =MID(W6,3,1) | AZ6: =MID(W6,4,1) | BA6: =MID(X6,1,1) | BB6: =MID(X6,2,1) | BC6: =MID(X6,3,1) | BD6: =MID(X6,4,1) | BE6: =MID(Y6,1,1) | BF6: =MID(Y6,2,1) | BG6: =MID(Y6,3,1) | BH6: =MID(Y6,4,1) | BI6: =MID(Z6,1,1) | BJ6: =MID(Z6,2,1) | BK6: =MID(Z6,3,1) | BL6: =MID(Z6,4,1) | BM6: =MID(AA6,1,1) | BN6: =MID(AA6,2,1) | BO6: =MID(AA6,3,1) | BP6: =MID(AA6,4,1) | BQ6: =MID(AB6,1,1) | BR6: =MID(AB6,2,1) | BS6: =MID(AB6,3,1) | BT6: =MID(AB6,4,1) | BU6: =MID(AC6,1,1) | BV6: =MID(AC6,2,1) | BW6: =MID(AC6,3,1) | BX6: =MID(AC6,4,1) | BY6: =MID(AD6,1,1) | BZ6: =MID(AD6,2,1) | CA6: =MID(AD6,3,1) | CB6: =MID(AD6,4,1) | CC6: =MID(AE6,1,1) | CD6: =MID(AE6,2,1) | CE6: =MID(AE6,3,1) | CF6: =MID(AE6,4,1) | CG6: =MID(AF6,1,1) | CH6: =MID(AF6,2,1) | CI6: =MID(AF6,3,1) | CJ6: =MID(AF6,4,1) | CK6: =MID(AG6,1,1) | CL6: =MID(AG6,2,1) | CM6: =MID(AG6,3,1) | CN6: =MID(AG6,4,1) | CO6: =MID(AH6,1,1) | CP6: =MID(AH6,2,1) | CQ6: =MID(AH6,3,1) | CR6: =MID(AH6,4,1) | CS6: =MID(AI6,1,1) | CT6: =MID(AI6,2,1) | CU6: =MID(AI6,3,1) | CV6: =MID(AI6,4,1) | CX6: 023456ABCD132536 | CY6: =MID($CX6,1,1) | CZ6: =MID($CX6,2,1) | DA6: =MID($CX6,3,1) | DB6: =MID($CX6,4,1) | DC6: =MID($CX6,5,1) | DD6: =MID($CX6,6,1) | DE6: =MID($CX6,7,1) | DF6: =MID($CX6,8,1) | DG6: =MID($CX6,9,1) | DH6: =MID($CX6,10,1) | DI6: =MID($CX6,11,1) | DJ6: =MID($CX6,12,1) | DK6: =MID($CX6,13,1) | DL6: =MID($CX6,14,1) | DM6: =MID($CX6,15,1) | DN6: =MID($CX6,16,1) | DP6: =DEC2BIN(HEX2DEC(CY6),4) | DQ6: =DEC2BIN(HEX2DEC(CZ6),4) | DR6: =DEC2BIN(HEX2DEC(DA6),4) | DS6: =DEC2BIN(HEX2DEC(DB6),4) | DT6: =DEC2BIN(HEX2DEC(DC6),4) | DU6: =DEC2BIN(HEX2DEC(DD6),4) | DV6: =DEC2BIN(HEX2DEC(DE6),4) | DW6: =DEC2BIN(HEX2DEC(DF6),4) | ... EE6: =DEC2BIN(HEX2DEC(DN6),4) | EG6: =MID(DP6,1,1) | EH6: =MID(DP6,2,1) | EI6: =MID(DP6,3,1) | EJ6: =MID(DP6,4,1) | EK6: =MID(DQ6,1,1) | EL6: =MID(DQ6,2,1) | EM6: =MID(DQ6,3,1) | EN6: =MID(DQ6,4,1) | EO6: =MID(DR6,1,1) | EP6: =MID(DR6,2,1) | EQ6: =MID(DR6,3,1) | ER6: =MID(DR6,4,1) | ES6: =MID(DS6,1,1) | ET6: =MID(DS6,2,1) | EU6: =MID(DS6,3,1) | EV6: =MID(DS6,4,1) | EW6: =MID(DT6,1,1) | EX6: =MID(DT6,2,1) | EY6: =MID(DT6,3,1) | EZ6: =MID(DT6,4,1) | FA6: =MID(DU6,1,1) | FB6: =MID(DU6,2,1) | FC6: =MID(DU6,3,1) | FD6: =MID(DU6,4,1) | FE6: =MID(DV6,1,1) | FF6: =MID(DV6,2,1) | FG6: =MID(DV6,3,1) | FH6: =MID(DV6,4,1) | FI6: =MID(DW6,1,1) | FJ6: =MID(DW6,2,1) | FK6: =MID(DW6,3,1) | FL6: =MID(DW6,4,1) | FM6: =MID(DX6,1,1) | FN6: =MID(DX6,2,1) | FO6: =MID(DX6,3,1) | FP6: =MID(DX6,4,1) | FQ6: =MID(DY6,1,1) | FR6: =MID(DY6,2,1) | FS6: =MID(DY6,3,1) | FT6: =MID(DY6,4,1) | FU6: =MID(DZ6,1,1) | FV6: =MID(DZ6,2,1) | FW6: =MID(DZ6,3,1) | FX6: =MID(DZ6,4,1) | FY6: =MID(EA6,1,1) | FZ6: =MID(EA6,2,1) | GA6: =MID(EA6,3,1) | GB6: =MID(EA6,4,1) | GC6: =MID(EB6,1,1) | GD6: =MID(EB6,2,1) | GE6: =MID(EB6,3,1) | GF6: =MID(EB6,4,1) | GG6: =MID(EC6,1,1) | GH6: =MID(EC6,2,1) | GI6: =MID(EC6,3,1) | GJ6: =MID(EC6,4,1) | GK6: =MID(ED6,1,1) | GL6: =MID(ED6,2,1) | GM6: =MID(ED6,3,1) | GN6: =MID(ED6,4,1) | GO6: =MID(EE6,1,1) | GP6: =MID(EE6,2,1) | GQ6: =MID(EE6,3,1) | GR6: =MID(EE6,4,1) | GT6: C0B7A8D05F3A829C | GU6: =MID($GT6,1,1) | GV6: =MID($GT6,2,1) | GW6: =MID($GT6,3,1) | GX6: =MID($GT6,4,1) | GY6: =MID($GT6,5,1) | GZ6: =MID($GT6,6,1) | HA6: =MID($GT6,7,1) | HB6: =MID($GT6,8,1) | HC6: =MID($GT6,9,1) | HD6: =MID($GT6,10,1) | HE6: =MID($GT6,11,1) | HF6: =MID($GT6,12,1) | HG6: =MID($GT6,13,1) | HH6: =MID($GT6,14,1) | HI6: =MID($GT6,15,1) | HJ6: =MID($GT6,16,1) | HL6: =DEC2BIN(HEX2DEC(GU6),4) | HM6: =DEC2BIN(HEX2DEC(GV6),4) | HN6: =DEC2BIN(HEX2DEC(GW6),4) | HO6: =DEC2BIN(HEX2DEC(GX6),4) | HP6: =DEC2BIN(HEX2DEC(GY6),4) | HQ6: =DEC2BIN(HEX2DEC(GZ6),4) | HR6: =DEC2BIN(HEX2DEC(HA6),4) | HS6: =DEC2BIN(HEX2DEC(HB6),4) | ... IA6: =DEC2BIN(HEX2DEC(HJ6),4) | IC6: =MID(HL6,1,1) | ID6: =MID(HL6,2,1) | IE6: =MID(HL6,3,1) | IF6: =MID(HL6,4,1) | IG6: =MID(HM6,1,1) | IH6: =MID(HM6,2,1) | II6: =MID(HM6,3,1) | IJ6: =MID(HM6,4,1) | IK6: =MID(HN6,1,1) | IL6: =MID(HN6,2,1) | IM6: =MID(HN6,3,1) | IN6: =MID(HN6,4,1) | IO6: =MID(HO6,1,1) | IP6: =MID(HO6,2,1) | IQ6: =MID(HO6,3,1) | IR6: =MID(HO6,4,1) | IS6: =MID(HP6,1,1) | IT6: =MID(HP6,2,1) | IU6: =MID(HP6,3,1) | IV6: =MID(HP6,4,1) | IW6: =MID(HQ6,1,1) | IX6: =MID(HQ6,2,1) | IY6: =MID(HQ6,3,1) | IZ6: =MID(HQ6,4,1) | JA6: =MID(HR6,1,1) | JB6: =MID(HR6,2,1) | JC6: =MID(HR6,3,1) | JD6: =MID(HR6,4,1) | JE6: =MID(HS6,1,1) | JF6: =MID(HS6,2,1) | JG6: =MID(HS6,3,1) | JH6: =MID(HS6,4,1) | JI6: =MID(HT6,1,1) | JJ6: =MID(HT6,2,1) | JK6: =MID(HT6,3,1) | JL6: =MID(HT6,4,1) | JM6: =MID(HU6,1,1) | JN6: =MID(HU6,2,1) | JO6: =MID(HU6,3,1) | JP6: =MID(HU6,4,1) | JQ6: =MID(HV6,1,1) | JR6: =MID(HV6,2,1) | JS6: =MID(HV6,3,1) | JT6: =MID(HV6,4,1) | JU6: =MID(HW6,1,1) | JV6: =MID(HW6,2,1) | JW6: =MID(HW6,3,1) | JX6: =MID(HW6,4,1) | JY6: =MID(HX6,1,1) | JZ6: =MID(HX6,2,1) | KA6: =MID(HX6,3,1) | KB6: =MID(HX6,4,1) | KC6: =MID(HY6,1,1) | KD6: =MID(HY6,2,1) | KE6: =MID(HY6,3,1) | KF6: =MID(HY6,4,1) | KG6: =MID(HZ6,1,1) | KH6: =MID(HZ6,2,1) | KI6: =MID(HZ6,3,1) | KJ6: =MID(HZ6,4,1) | KK6: =MID(IA6,1,1) | KL6: =MID(IA6,2,1) | KM6: =MID(IA6,3,1) | KN6: =MID(IA6,4,1) | KP6: 22AF081E9DD9EF8A | KQ6: =MID($KP6,1,1) | KR6: =MID($KP6,2,1) | KS6: =MID($KP6,3,1) | KT6: =MID($KP6,4,1) | KU6: =MID($KP6,5,1) | KV6: =MID($KP6,6,1) | KW6: =MID($KP6,7,1) | KX6: =MID($KP6,8,1) | KY6: =MID($KP6,9,1) | KZ6: =MID($KP6,10,1) | LA6: =MID($KP6,11,1) | LB6: =MID($KP6,12,1) | LC6: =MID($KP6,13,1) | LD6: =MID($KP6,14,1) | LE6: =MID($KP6,15,1) | LF6: =MID($KP6,16,1) | LH6: =DEC2BIN(HEX2DEC(KQ6),4) | LI6: =DEC2BIN(HEX2DEC(KR6),4) | LJ6: =DEC2BIN(HEX2DEC(KS6),4) | LK6: =DEC2BIN(HEX2DEC(KT6),4) | LL6: =DEC2BIN(HEX2DEC(KU6),4) | LM6: =DEC2BIN(HEX2DEC(KV6),4) | LN6: =DEC2BIN(HEX2DEC(KW6),4) | LO6: =DEC2BIN(HEX2DEC(KX6),4) | ... LW6: =DEC2BIN(HEX2DEC(LF6),4) | LY6: =MID(LH6,1,1) | LZ6: =MID(LH6,2,1) | MA6: =MID(LH6,3,1) | MB6: =MID(LH6,4,1) | MC6: =MID(LI6,1,1) | MD6: =MID(LI6,2,1) | ME6: =MID(LI6,3,1) | MF6: =MID(LI6,4,1) | MG6: =MID(LJ6,1,1) | MH6: =MID(LJ6,2,1) | MI6: =MID(LJ6,3,1) | MJ6: =MID(LJ6,4,1) | MK6: =MID(LK6,1,1) | ML6: =MID(LK6,2,1) | MM6: =MID(LK6,3,1) | MN6: =MID(LK6,4,1) | MO6: =MID(LL6,1,1) | MP6: =MID(LL6,2,1) | MQ6: =MID(LL6,3,1) | MR6: =MID(LL6,4,1) | MS6: =MID(LM6,1,1) | MT6: =MID(LM6,2,1) | MU6: =MID(LM6,3,1) | MV6: =MID(LM6,4,1) | MW6: =MID(LN6,1,1) | MX6: =MID(LN6,2,1) | MY6: =MID(LN6,3,1) | MZ6: =MID(LN6,4,1) | NA6: =MID(LO6,1,1) | NB6: =MID(LO6,2,1) | NC6: =MID(LO6,3,1) | ND6: =MID(LO6,4,1) | NE6: =MID(LP6,1,1) | NF6: =MID(LP6,2,1) | NG6: =MID(LP6,3,1) | NH6: =MID(LP6,4,1) | NI6: =MID(LQ6,1,1) | NJ6: =MID(LQ6,2,1) | NK6: =MID(LQ6,3,1) | NL6: =MID(LQ6,4,1) | NM6: =MID(LR6,1,1) | NN6: =MID(LR6,2,1) | NO6: =MID(LR6,3,1) | NP6: =MID(LR6,4,1) | NQ6: =MID(LS6,1,1) | NR6: =MID(LS6,2,1) | NS6: =MID(LS6,3,1) | NT6: =MID(LS6,4,1) | NU6: =MID(LT6,1,1) | NV6: =MID(LT6,2,1) | NW6: =MID(LT6,3,1) | NX6: =MID(LT6,4,1) | NY6: =MID(LU6,1,1) | NZ6: =MID(LU6,2,1) | OA6: =MID(LU6,3,1) | OB6: =MID(LU6,4,1) | OC6: =MID(LV6,1,1) | OD6: =MID(LV6,2,1) | OE6: =MID(LV6,3,1) | OF6: =MID(LV6,4,1) | OG6: =MID(LW6,1,1) | OH6: =MID(LW6,2,1) | OI6: =MID(LW6,3,1) | OJ6: =MID(LW6,4,1) | OL6: =MOD(IC6+LY6,2) | OM6: =MOD(ID6+LZ6,2) | ON6: =MOD(IE6+MA6,2) | OO6: =MOD(IF6+MB6,2) | OP6: =MOD(IG6+MC6,2) | OQ6: =MOD(IH6+MD6,2) | OR6: =MOD(II6+ME6,2) | OS6: =MOD(IJ6+MF6,2) | ... QW6: =MOD(KN6+OJ6,2) | QY6: =SUM(OL6:QW6)
A7: 123456ABCD132536 | B7: 5 | C7: =MID($A7,1,1) | D7: =MID($A7,2,1) | E7: =MID($A7,3,1) | F7: =MID($A7,4,1) | G7: =MID($A7,5,1) | H7: =MID($A7,6,1) | I7: =MID($A7,7,1) | J7: =MID($A7,8,1) | K7: =MID($A7,9,1) | L7: =MID($A7,10,1) | M7: =MID($A7,11,1) | N7: =MID($A7,12,1) | O7: =MID($A7,13,1) | P7: =MID($A7,14,1) | Q7: =MID($A7,15,1) | R7: =MID($A7,16,1) | T7: =DEC2BIN(HEX2DEC(C7),4) | U7: =DEC2BIN(HEX2DEC(D7),4) | V7: =DEC2BIN(HEX2DEC(E7),4) | W7: =DEC2BIN(HEX2DEC(F7),4) | X7: =DEC2BIN(HEX2DEC(G7),4) | Y7: =DEC2BIN(HEX2DEC(H7),4) | Z7: =DEC2BIN(HEX2DEC(I7),4) | AA7: =DEC2BIN(HEX2DEC(J7),4) | ... AI7: =DEC2BIN(HEX2DEC(R7),4) | AK7: =MID(T7,1,1) | AL7: =MID(T7,2,1) | AM7: =MID(T7,3,1) | AN7: =MID(T7,4,1) | AO7: =MID(U7,1,1) | AP7: =MID(U7,2,1) | AQ7: =MID(U7,3,1) | AR7: =MID(U7,4,1) | AS7: =MID(V7,1,1) | AT7: =MID(V7,2,1) | AU7: =MID(V7,3,1) | AV7: =MID(V7,4,1) | AW7: =MID(W7,1,1) | AX7: =MID(W7,2,1) | AY7: =MID(W7,3,1) | AZ7: =MID(W7,4,1) | BA7: =MID(X7,1,1) | BB7: =MID(X7,2,1) | BC7: =MID(X7,3,1) | BD7: =MID(X7,4,1) | BE7: =MID(Y7,1,1) | BF7: =MID(Y7,2,1) | BG7: =MID(Y7,3,1) | BH7: =MID(Y7,4,1) | BI7: =MID(Z7,1,1) | BJ7: =MID(Z7,2,1) | BK7: =MID(Z7,3,1) | BL7: =MID(Z7,4,1) | BM7: =MID(AA7,1,1) | BN7: =MID(AA7,2,1) | BO7: =MID(AA7,3,1) | BP7: =MID(AA7,4,1) | BQ7: =MID(AB7,1,1) | BR7: =MID(AB7,2,1) | BS7: =MID(AB7,3,1) | BT7: =MID(AB7,4,1) | BU7: =MID(AC7,1,1) | BV7: =MID(AC7,2,1) | BW7: =MID(AC7,3,1) | BX7: =MID(AC7,4,1) | BY7: =MID(AD7,1,1) | BZ7: =MID(AD7,2,1) | CA7: =MID(AD7,3,1) | CB7: =MID(AD7,4,1) | CC7: =MID(AE7,1,1) | CD7: =MID(AE7,2,1) | CE7: =MID(AE7,3,1) | CF7: =MID(AE7,4,1) | CG7: =MID(AF7,1,1) | CH7: =MID(AF7,2,1) | CI7: =MID(AF7,3,1) | CJ7: =MID(AF7,4,1) | CK7: =MID(AG7,1,1) | CL7: =MID(AG7,2,1) | CM7: =MID(AG7,3,1) | CN7: =MID(AG7,4,1) | CO7: =MID(AH7,1,1) | CP7: =MID(AH7,2,1) | CQ7: =MID(AH7,3,1) | CR7: =MID(AH7,4,1) | CS7: =MID(AI7,1,1) | CT7: =MID(AI7,2,1) | CU7: =MID(AI7,3,1) | CV7: =MID(AI7,4,1) | CX7: 1A3456ABCD132536 | CY7: =MID($CX7,1,1) | CZ7: =MID($CX7,2,1) | DA7: =MID($CX7,3,1) | DB7: =MID($CX7,4,1) | DC7: =MID($CX7,5,1) | DD7: =MID($CX7,6,1) | DE7: =MID($CX7,7,1) | DF7: =MID($CX7,8,1) | DG7: =MID($CX7,9,1) | DH7: =MID($CX7,10,1) | DI7: =MID($CX7,11,1) | DJ7: =MID($CX7,12,1) | DK7: =MID($CX7,13,1) | DL7: =MID($CX7,14,1) | DM7: =MID($CX7,15,1) | DN7: =MID($CX7,16,1) | DP7: =DEC2BIN(HEX2DEC(CY7),4) | DQ7: =DEC2BIN(HEX2DEC(CZ7),4) | DR7: =DEC2BIN(HEX2DEC(DA7),4) | DS7: =DEC2BIN(HEX2DEC(DB7),4) | DT7: =DEC2BIN(HEX2DEC(DC7),4) | DU7: =DEC2BIN(HEX2DEC(DD7),4) | DV7: =DEC2BIN(HEX2DEC(DE7),4) | DW7: =DEC2BIN(HEX2DEC(DF7),4) | ... EE7: =DEC2BIN(HEX2DEC(DN7),4) | EG7: =MID(DP7,1,1) | EH7: =MID(DP7,2,1) | EI7: =MID(DP7,3,1) | EJ7: =MID(DP7,4,1) | EK7: =MID(DQ7,1,1) | EL7: =MID(DQ7,2,1) | EM7: =MID(DQ7,3,1) | EN7: =MID(DQ7,4,1) | EO7: =MID(DR7,1,1) | EP7: =MID(DR7,2,1) | EQ7: =MID(DR7,3,1) | ER7: =MID(DR7,4,1) | ES7: =MID(DS7,1,1) | ET7: =MID(DS7,2,1) | EU7: =MID(DS7,3,1) | EV7: =MID(DS7,4,1) | EW7: =MID(DT7,1,1) | EX7: =MID(DT7,2,1) | EY7: =MID(DT7,3,1) | EZ7: =MID(DT7,4,1) | FA7: =MID(DU7,1,1) | FB7: =MID(DU7,2,1) | FC7: =MID(DU7,3,1) | FD7: =MID(DU7,4,1) | FE7: =MID(DV7,1,1) | FF7: =MID(DV7,2,1) | FG7: =MID(DV7,3,1) | FH7: =MID(DV7,4,1) | FI7: =MID(DW7,1,1) | FJ7: =MID(DW7,2,1) | FK7: =MID(DW7,3,1) | FL7: =MID(DW7,4,1) | FM7: =MID(DX7,1,1) | FN7: =MID(DX7,2,1) | FO7: =MID(DX7,3,1) | FP7: =MID(DX7,4,1) | FQ7: =MID(DY7,1,1) | FR7: =MID(DY7,2,1) | FS7: =MID(DY7,3,1) | FT7: =MID(DY7,4,1) | FU7: =MID(DZ7,1,1) | FV7: =MID(DZ7,2,1) | FW7: =MID(DZ7,3,1) | FX7: =MID(DZ7,4,1) | FY7: =MID(EA7,1,1) | FZ7: =MID(EA7,2,1) | GA7: =MID(EA7,3,1) | GB7: =MID(EA7,4,1) | GC7: =MID(EB7,1,1) | GD7: =MID(EB7,2,1) | GE7: =MID(EB7,3,1) | GF7: =MID(EB7,4,1) | GG7: =MID(EC7,1,1) | GH7: =MID(EC7,2,1) | GI7: =MID(EC7,3,1) | GJ7: =MID(EC7,4,1) | GK7: =MID(ED7,1,1) | GL7: =MID(ED7,2,1) | GM7: =MID(ED7,3,1) | GN7: =MID(ED7,4,1) | GO7: =MID(EE7,1,1) | GP7: =MID(EE7,2,1) | GQ7: =MID(EE7,3,1) | GR7: =MID(EE7,4,1) | GT7: C0B7A8D05F3A829C | GU7: =MID($GT7,1,1) | GV7: =MID($GT7,2,1) | GW7: =MID($GT7,3,1) | GX7: =MID($GT7,4,1) | GY7: =MID($GT7,5,1) | GZ7: =MID($GT7,6,1) | HA7: =MID($GT7,7,1) | HB7: =MID($GT7,8,1) | HC7: =MID($GT7,9,1) | HD7: =MID($GT7,10,1) | HE7: =MID($GT7,11,1) | HF7: =MID($GT7,12,1) | HG7: =MID($GT7,13,1) | HH7: =MID($GT7,14,1) | HI7: =MID($GT7,15,1) | HJ7: =MID($GT7,16,1) | HL7: =DEC2BIN(HEX2DEC(GU7),4) | HM7: =DEC2BIN(HEX2DEC(GV7),4) | HN7: =DEC2BIN(HEX2DEC(GW7),4) | HO7: =DEC2BIN(HEX2DEC(GX7),4) | HP7: =DEC2BIN(HEX2DEC(GY7),4) | HQ7: =DEC2BIN(HEX2DEC(GZ7),4) | HR7: =DEC2BIN(HEX2DEC(HA7),4) | HS7: =DEC2BIN(HEX2DEC(HB7),4) | ... IA7: =DEC2BIN(HEX2DEC(HJ7),4) | IC7: =MID(HL7,1,1) | ID7: =MID(HL7,2,1) | IE7: =MID(HL7,3,1) | IF7: =MID(HL7,4,1) | IG7: =MID(HM7,1,1) | IH7: =MID(HM7,2,1) | II7: =MID(HM7,3,1) | IJ7: =MID(HM7,4,1) | IK7: =MID(HN7,1,1) | IL7: =MID(HN7,2,1) | IM7: =MID(HN7,3,1) | IN7: =MID(HN7,4,1) | IO7: =MID(HO7,1,1) | IP7: =MID(HO7,2,1) | IQ7: =MID(HO7,3,1) | IR7: =MID(HO7,4,1) | IS7: =MID(HP7,1,1) | IT7: =MID(HP7,2,1) | IU7: =MID(HP7,3,1) | IV7: =MID(HP7,4,1) | IW7: =MID(HQ7,1,1) | IX7: =MID(HQ7,2,1) | IY7: =MID(HQ7,3,1) | IZ7: =MID(HQ7,4,1) | JA7: =MID(HR7,1,1) | JB7: =MID(HR7,2,1) | JC7: =MID(HR7,3,1) | JD7: =MID(HR7,4,1) | JE7: =MID(HS7,1,1) | JF7: =MID(HS7,2,1) | JG7: =MID(HS7,3,1) | JH7: =MID(HS7,4,1) | JI7: =MID(HT7,1,1) | JJ7: =MID(HT7,2,1) | JK7: =MID(HT7,3,1) | JL7: =MID(HT7,4,1) | JM7: =MID(HU7,1,1) | JN7: =MID(HU7,2,1) | JO7: =MID(HU7,3,1) | JP7: =MID(HU7,4,1) | JQ7: =MID(HV7,1,1) | JR7: =MID(HV7,2,1) | JS7: =MID(HV7,3,1) | JT7: =MID(HV7,4,1) | JU7: =MID(HW7,1,1) | JV7: =MID(HW7,2,1) | JW7: =MID(HW7,3,1) | JX7: =MID(HW7,4,1) | JY7: =MID(HX7,1,1) | JZ7: =MID(HX7,2,1) | KA7: =MID(HX7,3,1) | KB7: =MID(HX7,4,1) | KC7: =MID(HY7,1,1) | KD7: =MID(HY7,2,1) | KE7: =MID(HY7,3,1) | KF7: =MID(HY7,4,1) | KG7: =MID(HZ7,1,1) | KH7: =MID(HZ7,2,1) | KI7: =MID(HZ7,3,1) | KJ7: =MID(HZ7,4,1) | KK7: =MID(IA7,1,1) | KL7: =MID(IA7,2,1) | KM7: =MID(IA7,3,1) | KN7: =MID(IA7,4,1) | KP7: 7E73670E41F09E8C | KQ7: =MID($KP7,1,1) | KR7: =MID($KP7,2,1) | KS7: =MID($KP7,3,1) | KT7: =MID($KP7,4,1) | KU7: =MID($KP7,5,1) | KV7: =MID($KP7,6,1) | KW7: =MID($KP7,7,1) | KX7: =MID($KP7,8,1) | KY7: =MID($KP7,9,1) | KZ7: =MID($KP7,10,1) | LA7: =MID($KP7,11,1) | LB7: =MID($KP7,12,1) | LC7: =MID($KP7,13,1) | LD7: =MID($KP7,14,1) | LE7: =MID($KP7,15,1) | LF7: =MID($KP7,16,1) | LH7: =DEC2BIN(HEX2DEC(KQ7),4) | LI7: =DEC2BIN(HEX2DEC(KR7),4) | LJ7: =DEC2BIN(HEX2DEC(KS7),4) | LK7: =DEC2BIN(HEX2DEC(KT7),4) | LL7: =DEC2BIN(HEX2DEC(KU7),4) | LM7: =DEC2BIN(HEX2DEC(KV7),4) | LN7: =DEC2BIN(HEX2DEC(KW7),4) | LO7: =DEC2BIN(HEX2DEC(KX7),4) | ... LW7: =DEC2BIN(HEX2DEC(LF7),4) | LY7: =MID(LH7,1,1) | LZ7: =MID(LH7,2,1) | MA7: =MID(LH7,3,1) | MB7: =MID(LH7,4,1) | MC7: =MID(LI7,1,1) | MD7: =MID(LI7,2,1) | ME7: =MID(LI7,3,1) | MF7: =MID(LI7,4,1) | MG7: =MID(LJ7,1,1) | MH7: =MID(LJ7,2,1) | MI7: =MID(LJ7,3,1) | MJ7: =MID(LJ7,4,1) | MK7: =MID(LK7,1,1) | ML7: =MID(LK7,2,1) | MM7: =MID(LK7,3,1) | MN7: =MID(LK7,4,1) | MO7: =MID(LL7,1,1) | MP7: =MID(LL7,2,1) | MQ7: =MID(LL7,3,1) | MR7: =MID(LL7,4,1) | MS7: =MID(LM7,1,1) | MT7: =MID(LM7,2,1) | MU7: =MID(LM7,3,1) | MV7: =MID(LM7,4,1) | MW7: =MID(LN7,1,1) | MX7: =MID(LN7,2,1) | MY7: =MID(LN7,3,1) | MZ7: =MID(LN7,4,1) | NA7: =MID(LO7,1,1) | NB7: =MID(LO7,2,1) | NC7: =MID(LO7,3,1) | ND7: =MID(LO7,4,1) | NE7: =MID(LP7,1,1) | NF7: =MID(LP7,2,1) | NG7: =MID(LP7,3,1) | NH7: =MID(LP7,4,1) | NI7: =MID(LQ7,1,1) | NJ7: =MID(LQ7,2,1) | NK7: =MID(LQ7,3,1) | NL7: =MID(LQ7,4,1) | NM7: =MID(LR7,1,1) | NN7: =MID(LR7,2,1) | NO7: =MID(LR7,3,1) | NP7: =MID(LR7,4,1) | NQ7: =MID(LS7,1,1) | NR7: =MID(LS7,2,1) | NS7: =MID(LS7,3,1) | NT7: =MID(LS7,4,1) | NU7: =MID(LT7,1,1) | NV7: =MID(LT7,2,1) | NW7: =MID(LT7,3,1) | NX7: =MID(LT7,4,1) | NY7: =MID(LU7,1,1) | NZ7: =MID(LU7,2,1) | OA7: =MID(LU7,3,1) | OB7: =MID(LU7,4,1) | OC7: =MID(LV7,1,1) | OD7: =MID(LV7,2,1) | OE7: =MID(LV7,3,1) | OF7: =MID(LV7,4,1) | OG7: =MID(LW7,1,1) | OH7: =MID(LW7,2,1) | OI7: =MID(LW7,3,1) | OJ7: =MID(LW7,4,1) | OL7: =MOD(IC7+LY7,2) | OM7: =MOD(ID7+LZ7,2) | ON7: =MOD(IE7+MA7,2) | OO7: =MOD(IF7+MB7,2) | OP7: =MOD(IG7+MC7,2) | OQ7: =MOD(IH7+MD7,2) | OR7: =MOD(II7+ME7,2) | OS7: =MOD(IJ7+MF7,2) | ... QW7: =MOD(KN7+OJ7,2) | QY7: =SUM(OL7:QW7)
A8: 123456ABCD132536 | B8: 6 | C8: =MID($A8,1,1) | D8: =MID($A8,2,1) | E8: =MID($A8,3,1) | F8: =MID($A8,4,1) | G8: =MID($A8,5,1) | H8: =MID($A8,6,1) | I8: =MID($A8,7,1) | J8: =MID($A8,8,1) | K8: =MID($A8,9,1) | L8: =MID($A8,10,1) | M8: =MID($A8,11,1) | N8: =MID($A8,12,1) | O8: =MID($A8,13,1) | P8: =MID($A8,14,1) | Q8: =MID($A8,15,1) | R8: =MID($A8,16,1) | T8: =DEC2BIN(HEX2DEC(C8),4) | U8: =DEC2BIN(HEX2DEC(D8),4) | V8: =DEC2BIN(HEX2DEC(E8),4) | W8: =DEC2BIN(HEX2DEC(F8),4) | X8: =DEC2BIN(HEX2DEC(G8),4) | Y8: =DEC2BIN(HEX2DEC(H8),4) | Z8: =DEC2BIN(HEX2DEC(I8),4) | AA8: =DEC2BIN(HEX2DEC(J8),4) | ... AI8: =DEC2BIN(HEX2DEC(R8),4) | AK8: =MID(T8,1,1) | AL8: =MID(T8,2,1) | AM8: =MID(T8,3,1) | AN8: =MID(T8,4,1) | AO8: =MID(U8,1,1) | AP8: =MID(U8,2,1) | AQ8: =MID(U8,3,1) | AR8: =MID(U8,4,1) | AS8: =MID(V8,1,1) | AT8: =MID(V8,2,1) | AU8: =MID(V8,3,1) | AV8: =MID(V8,4,1) | AW8: =MID(W8,1,1) | AX8: =MID(W8,2,1) | AY8: =MID(W8,3,1) | AZ8: =MID(W8,4,1) | BA8: =MID(X8,1,1) | BB8: =MID(X8,2,1) | BC8: =MID(X8,3,1) | BD8: =MID(X8,4,1) | BE8: =MID(Y8,1,1) | BF8: =MID(Y8,2,1) | BG8: =MID(Y8,3,1) | BH8: =MID(Y8,4,1) | BI8: =MID(Z8,1,1) | BJ8: =MID(Z8,2,1) | BK8: =MID(Z8,3,1) | BL8: =MID(Z8,4,1) | BM8: =MID(AA8,1,1) | BN8: =MID(AA8,2,1) | BO8: =MID(AA8,3,1) | BP8: =MID(AA8,4,1) | BQ8: =MID(AB8,1,1) | BR8: =MID(AB8,2,1) | BS8: =MID(AB8,3,1) | BT8: =MID(AB8,4,1) | BU8: =MID(AC8,1,1) | BV8: =MID(AC8,2,1) | BW8: =MID(AC8,3,1) | BX8: =MID(AC8,4,1) | BY8: =MID(AD8,1,1) | BZ8: =MID(AD8,2,1) | CA8: =MID(AD8,3,1) | CB8: =MID(AD8,4,1) | CC8: =MID(AE8,1,1) | CD8: =MID(AE8,2,1) | CE8: =MID(AE8,3,1) | CF8: =MID(AE8,4,1) | CG8: =MID(AF8,1,1) | CH8: =MID(AF8,2,1) | CI8: =MID(AF8,3,1) | CJ8: =MID(AF8,4,1) | CK8: =MID(AG8,1,1) | CL8: =MID(AG8,2,1) | CM8: =MID(AG8,3,1) | CN8: =MID(AG8,4,1) | CO8: =MID(AH8,1,1) | CP8: =MID(AH8,2,1) | CQ8: =MID(AH8,3,1) | CR8: =MID(AH8,4,1) | CS8: =MID(AI8,1,1) | CT8: =MID(AI8,2,1) | CU8: =MID(AI8,3,1) | CV8: =MID(AI8,4,1) | CX8: 163456ABCD132536 | CY8: =MID($CX8,1,1) | CZ8: =MID($CX8,2,1) | DA8: =MID($CX8,3,1) | DB8: =MID($CX8,4,1) | DC8: =MID($CX8,5,1) | DD8: =MID($CX8,6,1) | DE8: =MID($CX8,7,1) | DF8: =MID($CX8,8,1) | DG8: =MID($CX8,9,1) | DH8: =MID($CX8,10,1) | DI8: =MID($CX8,11,1) | DJ8: =MID($CX8,12,1) | DK8: =MID($CX8,13,1) | DL8: =MID($CX8,14,1) | DM8: =MID($CX8,15,1) | DN8: =MID($CX8,16,1) | DP8: =DEC2BIN(HEX2DEC(CY8),4) | DQ8: =DEC2BIN(HEX2DEC(CZ8),4) | DR8: =DEC2BIN(HEX2DEC(DA8),4) | DS8: =DEC2BIN(HEX2DEC(DB8),4) | DT8: =DEC2BIN(HEX2DEC(DC8),4) | DU8: =DEC2BIN(HEX2DEC(DD8),4) | DV8: =DEC2BIN(HEX2DEC(DE8),4) | DW8: =DEC2BIN(HEX2DEC(DF8),4) | ... EE8: =DEC2BIN(HEX2DEC(DN8),4) | EG8: =MID(DP8,1,1) | EH8: =MID(DP8,2,1) | EI8: =MID(DP8,3,1) | EJ8: =MID(DP8,4,1) | EK8: =MID(DQ8,1,1) | EL8: =MID(DQ8,2,1) | EM8: =MID(DQ8,3,1) | EN8: =MID(DQ8,4,1) | EO8: =MID(DR8,1,1) | EP8: =MID(DR8,2,1) | EQ8: =MID(DR8,3,1) | ER8: =MID(DR8,4,1) | ES8: =MID(DS8,1,1) | ET8: =MID(DS8,2,1) | EU8: =MID(DS8,3,1) | EV8: =MID(DS8,4,1) | EW8: =MID(DT8,1,1) | EX8: =MID(DT8,2,1) | EY8: =MID(DT8,3,1) | EZ8: =MID(DT8,4,1) | FA8: =MID(DU8,1,1) | FB8: =MID(DU8,2,1) | FC8: =MID(DU8,3,1) | FD8: =MID(DU8,4,1) | FE8: =MID(DV8,1,1) | FF8: =MID(DV8,2,1) | FG8: =MID(DV8,3,1) | FH8: =MID(DV8,4,1) | FI8: =MID(DW8,1,1) | FJ8: =MID(DW8,2,1) | FK8: =MID(DW8,3,1) | FL8: =MID(DW8,4,1) | FM8: =MID(DX8,1,1) | FN8: =MID(DX8,2,1) | FO8: =MID(DX8,3,1) | FP8: =MID(DX8,4,1) | FQ8: =MID(DY8,1,1) | FR8: =MID(DY8,2,1) | FS8: =MID(DY8,3,1) | FT8: =MID(DY8,4,1) | FU8: =MID(DZ8,1,1) | FV8: =MID(DZ8,2,1) | FW8: =MID(DZ8,3,1) | FX8: =MID(DZ8,4,1) | FY8: =MID(EA8,1,1) | FZ8: =MID(EA8,2,1) | GA8: =MID(EA8,3,1) | GB8: =MID(EA8,4,1) | GC8: =MID(EB8,1,1) | GD8: =MID(EB8,2,1) | GE8: =MID(EB8,3,1) | GF8: =MID(EB8,4,1) | GG8: =MID(EC8,1,1) | GH8: =MID(EC8,2,1) | GI8: =MID(EC8,3,1) | GJ8: =MID(EC8,4,1) | GK8: =MID(ED8,1,1) | GL8: =MID(ED8,2,1) | GM8: =MID(ED8,3,1) | GN8: =MID(ED8,4,1) | GO8: =MID(EE8,1,1) | GP8: =MID(EE8,2,1) | GQ8: =MID(EE8,3,1) | GR8: =MID(EE8,4,1) | GT8: C0B7A8D05F3A829C | GU8: =MID($GT8,1,1) | GV8: =MID($GT8,2,1) | GW8: =MID($GT8,3,1) | GX8: =MID($GT8,4,1) | GY8: =MID($GT8,5,1) | GZ8: =MID($GT8,6,1) | HA8: =MID($GT8,7,1) | HB8: =MID($GT8,8,1) | HC8: =MID($GT8,9,1) | HD8: =MID($GT8,10,1) | HE8: =MID($GT8,11,1) | HF8: =MID($GT8,12,1) | HG8: =MID($GT8,13,1) | HH8: =MID($GT8,14,1) | HI8: =MID($GT8,15,1) | HJ8: =MID($GT8,16,1) | HL8: =DEC2BIN(HEX2DEC(GU8),4) | HM8: =DEC2BIN(HEX2DEC(GV8),4) | HN8: =DEC2BIN(HEX2DEC(GW8),4) | HO8: =DEC2BIN(HEX2DEC(GX8),4) | HP8: =DEC2BIN(HEX2DEC(GY8),4) | HQ8: =DEC2BIN(HEX2DEC(GZ8),4) | HR8: =DEC2BIN(HEX2DEC(HA8),4) | HS8: =DEC2BIN(HEX2DEC(HB8),4) | ... IA8: =DEC2BIN(HEX2DEC(HJ8),4) | IC8: =MID(HL8,1,1) | ID8: =MID(HL8,2,1) | IE8: =MID(HL8,3,1) | IF8: =MID(HL8,4,1) | IG8: =MID(HM8,1,1) | IH8: =MID(HM8,2,1) | II8: =MID(HM8,3,1) | IJ8: =MID(HM8,4,1) | IK8: =MID(HN8,1,1) | IL8: =MID(HN8,2,1) | IM8: =MID(HN8,3,1) | IN8: =MID(HN8,4,1) | IO8: =MID(HO8,1,1) | IP8: =MID(HO8,2,1) | IQ8: =MID(HO8,3,1) | IR8: =MID(HO8,4,1) | IS8: =MID(HP8,1,1) | IT8: =MID(HP8,2,1) | IU8: =MID(HP8,3,1) | IV8: =MID(HP8,4,1) | IW8: =MID(HQ8,1,1) | IX8: =MID(HQ8,2,1) | IY8: =MID(HQ8,3,1) | IZ8: =MID(HQ8,4,1) | JA8: =MID(HR8,1,1) | JB8: =MID(HR8,2,1) | JC8: =MID(HR8,3,1) | JD8: =MID(HR8,4,1) | JE8: =MID(HS8,1,1) | JF8: =MID(HS8,2,1) | JG8: =MID(HS8,3,1) | JH8: =MID(HS8,4,1) | JI8: =MID(HT8,1,1) | JJ8: =MID(HT8,2,1) | JK8: =MID(HT8,3,1) | JL8: =MID(HT8,4,1) | JM8: =MID(HU8,1,1) | JN8: =MID(HU8,2,1) | JO8: =MID(HU8,3,1) | JP8: =MID(HU8,4,1) | JQ8: =MID(HV8,1,1) | JR8: =MID(HV8,2,1) | JS8: =MID(HV8,3,1) | JT8: =MID(HV8,4,1) | JU8: =MID(HW8,1,1) | JV8: =MID(HW8,2,1) | JW8: =MID(HW8,3,1) | JX8: =MID(HW8,4,1) | JY8: =MID(HX8,1,1) | JZ8: =MID(HX8,2,1) | KA8: =MID(HX8,3,1) | KB8: =MID(HX8,4,1) | KC8: =MID(HY8,1,1) | KD8: =MID(HY8,2,1) | KE8: =MID(HY8,3,1) | KF8: =MID(HY8,4,1) | KG8: =MID(HZ8,1,1) | KH8: =MID(HZ8,2,1) | KI8: =MID(HZ8,3,1) | KJ8: =MID(HZ8,4,1) | KK8: =MID(IA8,1,1) | KL8: =MID(IA8,2,1) | KM8: =MID(IA8,3,1) | KN8: =MID(IA8,4,1) | KP8: 4DCDEF3CD51B3F72 | KQ8: =MID($KP8,1,1) | KR8: =MID($KP8,2,1) | KS8: =MID($KP8,3,1) | KT8: =MID($KP8,4,1) | KU8: =MID($KP8,5,1) | KV8: =MID($KP8,6,1) | KW8: =MID($KP8,7,1) | KX8: =MID($KP8,8,1) | KY8: =MID($KP8,9,1) | KZ8: =MID($KP8,10,1) | LA8: =MID($KP8,11,1) | LB8: =MID($KP8,12,1) | LC8: =MID($KP8,13,1) | LD8: =MID($KP8,14,1) | LE8: =MID($KP8,15,1) | LF8: =MID($KP8,16,1) | LH8: =DEC2BIN(HEX2DEC(KQ8),4) | LI8: =DEC2BIN(HEX2DEC(KR8),4) | LJ8: =DEC2BIN(HEX2DEC(KS8),4) | LK8: =DEC2BIN(HEX2DEC(KT8),4) | LL8: =DEC2BIN(HEX2DEC(KU8),4) | LM8: =DEC2BIN(HEX2DEC(KV8),4) | LN8: =DEC2BIN(HEX2DEC(KW8),4) | LO8: =DEC2BIN(HEX2DEC(KX8),4) | ... LW8: =DEC2BIN(HEX2DEC(LF8),4) | LY8: =MID(LH8,1,1) | LZ8: =MID(LH8,2,1) | MA8: =MID(LH8,3,1) | MB8: =MID(LH8,4,1) | MC8: =MID(LI8,1,1) | MD8: =MID(LI8,2,1) | ME8: =MID(LI8,3,1) | MF8: =MID(LI8,4,1) | MG8: =MID(LJ8,1,1) | MH8: =MID(LJ8,2,1) | MI8: =MID(LJ8,3,1) | MJ8: =MID(LJ8,4,1) | MK8: =MID(LK8,1,1) | ML8: =MID(LK8,2,1) | MM8: =MID(LK8,3,1) | MN8: =MID(LK8,4,1) | MO8: =MID(LL8,1,1) | MP8: =MID(LL8,2,1) | MQ8: =MID(LL8,3,1) | MR8: =MID(LL8,4,1) | MS8: =MID(LM8,1,1) | MT8: =MID(LM8,2,1) | MU8: =MID(LM8,3,1) | MV8: =MID(LM8,4,1) | MW8: =MID(LN8,1,1) | MX8: =MID(LN8,2,1) | MY8: =MID(LN8,3,1) | MZ8: =MID(LN8,4,1) | NA8: =MID(LO8,1,1) | NB8: =MID(LO8,2,1) | NC8: =MID(LO8,3,1) | ND8: =MID(LO8,4,1) | NE8: =MID(LP8,1,1) | NF8: =MID(LP8,2,1) | NG8: =MID(LP8,3,1) | NH8: =MID(LP8,4,1) | NI8: =MID(LQ8,1,1) | NJ8: =MID(LQ8,2,1) | NK8: =MID(LQ8,3,1) | NL8: =MID(LQ8,4,1) | NM8: =MID(LR8,1,1) | NN8: =MID(LR8,2,1) | NO8: =MID(LR8,3,1) | NP8: =MID(LR8,4,1) | NQ8: =MID(LS8,1,1) | NR8: =MID(LS8,2,1) | NS8: =MID(LS8,3,1) | NT8: =MID(LS8,4,1) | NU8: =MID(LT8,1,1) | NV8: =MID(LT8,2,1) | NW8: =MID(LT8,3,1) | NX8: =MID(LT8,4,1) | NY8: =MID(LU8,1,1) | NZ8: =MID(LU8,2,1) | OA8: =MID(LU8,3,1) | OB8: =MID(LU8,4,1) | OC8: =MID(LV8,1,1) | OD8: =MID(LV8,2,1) | OE8: =MID(LV8,3,1) | OF8: =MID(LV8,4,1) | OG8: =MID(LW8,1,1) | OH8: =MID(LW8,2,1) | OI8: =MID(LW8,3,1) | OJ8: =MID(LW8,4,1) | OL8: =MOD(IC8+LY8,2) | OM8: =MOD(ID8+LZ8,2) | ON8: =MOD(IE8+MA8,2) | OO8: =MOD(IF8+MB8,2) | OP8: =MOD(IG8+MC8,2) | OQ8: =MOD(IH8+MD8,2) | OR8: =MOD(II8+ME8,2) | OS8: =MOD(IJ8+MF8,2) | ... QW8: =MOD(KN8+OJ8,2) | QY8: =SUM(OL8:QW8)
